Workbook
Name A: #REF!
Name B: #REF!
Name CC: #REF!
Name D: #REF!
Name E: #REF!
Name F: #REF!
Name G: #REF!
Name H: '2019'!$A$1:$M$690
Name I: '2020'!$A$1:$M$661
Name J: '2021'!$A$1:$M$646
Name K: '2022'!$A$1:$M$659
Name L: '2023'!$A$1:$M$635
Name y_2020: '2020'!$A$1:$M$661
Name y_2021: '2021'!$A$1:$M$646
Name y_2022: '2022'!$A$1:$M$659
Name y_2023: '2023'!$A$1:$M$635
Name y_2029: '2019'!$A$1:$M$690

Sheet 2019
A1: Region / ALC Code | B1: Jan | C1: Feb | D1: Mar | E1: Apr | F1: May | G1: Jun | H1: Jul | I1: Aug | J1: Sep | K1: Oct | L1: Nov | M1: Dec
A2: 17210059 | B2: 17 | C2: 6 | D2: 59 | E2: 41 | F2: 14 | G2: 9 | H2: 15 | I2: 6 | J2: 6 | K2: 14 | L2: 7 | M2: 3
A3: 32210002 | B3: 5 | C3: 23 | D3: 0 | E3: 124 | F3: 55 | G3: 23 | H3: 13 | I3: 18 | J3: 11 | K3: 8 | L3: 7 | M3: 7
A4: 39210001 | B4: 12 | C4: 2 | D4: 27 | E4: 41 | F4: 21 | G4: 0 | H4: 19 | I4: 19 | J4: 3 | K4: 14 | L4: 4 | M4: 5
A5: 57210018 | B5: 5 | C5: 7 | D5: 10 | E5: 60 | F5: 40 | G5: 14 | H5: 11 | I5: 1 | J5: 10 | K5: 7 | L5: 4 | M5: 8
A6: 17210060 | B6: 151 | C6: 13 | D6: 0 | E6: 575 | F6: 63 | G6: 17 | H6: 34 | I6: 29 | J6: 10 | K6: 9 | L6: 8 | M6: 14
A7: 78210106 | B7: 1 | C7: 3 | D7: 0 | E7: 25 | F7: 0 | G7: 2 | H7: 5 | I7: 7 | J7: 0 | K7: 7 | L7: 0 | M7: 0
A8: 13210002 | B8: 0 | C8: 2 | D8: 0 | E8: 21 | F8: 1 | G8: 0 | H8: 9 | I8: 0 | J8: 5 | K8: 0 | L8: 2 | M8: 0
A9: 13210003 | B9: 12 | C9: 4 | D9: 7 | E9: 106 | F9: 17 | G9: 2 | H9: 15 | I9: 0 | J9: 7 | K9: 11 | L9: 0 | M9: 0
A10: 37210001 | B10: 18 | C10: 10 | D10: 50 | E10: 67 | F10: 10 | G10: 9 | H10: 5 | I10: 8 | J10: 4 | K10: 6 | L10: 3 | M10: 5
A11: 34210010 | B11: 4 | C11: 6 | D11: 9 | E11: 22 | F11: 11 | G11: 2 | H11: 7 | I11: 8 | J11: 8 | K11: 3 | L11: 11 | M11: 1
A12: 15210008 | B12: 9 | C12: 0 | D12: 25 | E12: 35 | F12: 18 | G12: 6 | H12: 7 | I12: 11 | J12: 0 | K12: 1 | L12: 0 | M12: 0
A13: 78210122 | B13: 0 | C13: 6 | D13: 8 | E13: 24 | F13: 9 | G13: 4 | H13: 5 | I13: 3 | J13: 0 | K13: 15 | L13: 2 | M13: 1
... A690: 26210135 | B690: 14 | C690: 4 | D690: 0 | E690: 5 | F690: 15 | G690: 8 | H690: 5 | I690: 0 | J690: 7 | K690: 0 | L690: 0 | M690: 0

Sheet 2020
A1: Region / ALC Code | B1: Jan | C1: Feb | D1: Mar | E1: Apr | F1: May | G1: Jun | H1: Jul | I1: Aug | J1: Sep | K1: Oct | L1: Nov | M1: Dec
A2: 17210059 | B2: 7 | C2: 3 | D2: 22 | E2: 42 | F2: 69 | G2: 2 | H2: 10 | I2: 20 | J2: 12 | K2: 6 | L2: 5 | M2: 0
A3: 32210002 | B3: 5 | C3: 60 | D3: 10 | E3: 98 | F3: 59 | G3: 18 | H3: 6 | I3: 8 | J3: 8 | K3: 9 | L3: 15 | M3: 0
A4: 39210001 | B4: 3 | C4: 6 | D4: 9 | E4: 0 | F4: 52 | G4: 11 | H4: 8 | I4: 5 | J4: 0 | K4: 1 | L4: 5 | M4: 0
A5: 57210018 | B5: 4 | C5: 3 | D5: 14 | E5: 18 | F5: 106 | G5: 4 | H5: 9 | I5: 5 | J5: 4 | K5: 1 | L5: 6 | M5: 0
A6: 17210060 | B6: 43 | C6: 15 | D6: 37 | E6: 263 | F6: 215 | G6: 18 | H6: 24 | I6: 22 | J6: 0 | K6: 10 | L6: 11 | M6: 0
A7: 13210003 | B7: 10 | C7: 0 | D7: 13 | E7: 0 | F7: 145 | G7: 42 | H7: 1 | I7: 8 | J7: 5 | K7: 0 | L7: 3 | M7: 0
A8: 37210001 | B8: 6 | C8: 7 | D8: 35 | E8: 40 | F8: 30 | G8: 12 | H8: 7 | I8: 7 | J8: 3 | K8: 7 | L8: 9 | M8: 0
A9: 34210010 | B9: 0 | C9: 1 | D9: 8 | E9: 0 | F9: 15 | G9: 1 | H9: 4 | I9: 0 | J9: 5 | K9: 13 | L9: 17 | M9: 0
A10: 15210008 | B10: 1 | C10: 1 | D10: 4 | E10: 10 | F10: 21 | G10: 0 | H10: 18 | I10: 8 | J10: 9 | K10: 6 | L10: 22 | M10: 0
A11: 78210122 | B11: 3 | C11: 4 | D11: 11 | E11: 12 | F11: 19 | G11: 9 | H11: 4 | I11: 3 | J11: 2 | K11: 1 | L11: 10 | M11: 0
A12: 78210188 | B12: 9 | C12: 6 | D12: 11 | E12: 0 | F12: 35 | G12: 6 | H12: 7 | I12: 9 | J12: 3 | K12: 11 | L12: 4 | M12: 0
A13: 52210005 | B13: 29 | C13: 8 | D13: 65 | E13: 40 | F13: 39 | G13: 12 | H13: 5 | I13: 12 | J13: 12 | K13: 6 | L13: 0 | M13: 0
... A661: 26210135 | B661: 8 | C661: 0 | D661: 0 | E661: 22 | F661: 25 | G661: 0 | H661: 0 | I661: 0 | J661: 7 | K661: 4 | L661: 1 | M661: 0

Sheet 2021
A1: Region / ALC Code | B1: Jan | C1: Feb | D1: Mar | E1: Apr | F1: May | G1: Jun | H1: Jul | I1: Aug | J1: Sep | K1: Oct | L1: Nov | M1: Dec
A2: 17210059 | B2: 11 | C2: 0 | D2: 0 | E2: 117 | F2: 29 | G2: 0 | H2: 16 | I2: 0 | J2: 21 | K2: 0 | L2: 21 | M2: 0
A3: 32210002 | B3: 20 | C3: 0 | D3: 0 | E3: 86 | F3: 20 | G3: 0 | H3: 26 | I3: 0 | J3: 10 | K3: 0 | L3: 15 | M3: 0
A4: 39210001 | B4: 11 | C4: 0 | D4: 0 | E4: 56 | F4: 43 | G4: 0 | H4: 18 | I4: 0 | J4: 2 | K4: 0 | L4: 7 | M4: 0
A5: 57210018 | B5: 15 | C5: 0 | D5: 14 | E5: 91 | F5: 80 | G5: 0 | H5: 36 | I5: 0 | J5: 13 | K5: 0 | L5: 15 | M5: 0
A6: 17210060 | B6: 60 | C6: 0 | D6: 0 | E6: 315 | F6: 105 | G6: 0 | H6: 37 | I6: 0 | J6: 23 | K6: 0 | L6: 19 | M6: 0
A7: 13210003 | B7: 0 | C7: 0 | D7: 0 | E7: 92 | F7: 66 | G7: 0 | H7: 12 | I7: 0 | J7: 16 | K7: 0 | L7: 5 | M7: 0
A8: 37210001 | B8: 32 | C8: 0 | D8: 12 | E8: 82 | F8: 25 | G8: 0 | H8: 15 | I8: 0 | J8: 14 | K8: 0 | L8: 0 | M8: 0
A9: 34210010 | B9: 3 | C9: 0 | D9: 0 | E9: 109 | F9: 14 | G9: 0 | H9: 7 | I9: 0 | J9: 19 | K9: 0 | L9: 14 | M9: 0
A10: 15210008 | B10: 34 | C10: 0 | D10: 0 | E10: 29 | F10: 63 | G10: 0 | H10: 0 | I10: 0 | J10: 0 | K10: 0 | L10: 16 | M10: 0
A11: 78210122 | B11: 7 | C11: 0 | D11: 3 | E11: 21 | F11: 10 | G11: 0 | H11: 20 | I11: 0 | J11: 5 | K11: 0 | L11: 18 | M11: 0
A12: 78210188 | B12: 2 | C12: 0 | D12: 0 | E12: 3 | F12: 12 | G12: 0 | H12: 5 | I12: 0 | J12: 7 | K12: 0 | L12: 2 | M12: 0
A13: 52210005 | B13: 38 | C13: 0 | D13: 0 | E13: 153 | F13: 32 | G13: 0 | H13: 31 | I13: 0 | J13: 39 | K13: 0 | L13: 22 | M13: 0
... A641: 32210285 | B641: 0 | C641: 0 | D641: 0 | E641: 0 | F641: 15 | G641: 0 | H641: 0 | I641: 0 | J641: 0 | K641: 0 | L641: 24 | M641: 0
A642: 1J210310 | B642: 0 | C642: 0 | D642: 0 | E642: 53 | F642: 19 | G642: 0 | H642: 10 | I642: 0 | J642: 7 | K642: 0 | L642: 11 | M642: 0
A643: 52210297 | B643: 23 | C643: 0 | D643: 5 | E643: 22 | F643: 9 | G643: 0 | H643: 22 | I643: 0 | J643: 5 | K643: 0 | L643: 5 | M643: 0
A644: 87210025 | B644: 0 | C644: 0 | D644: 2 | E644: 10 | F644: 5 | G644: 0 | H644: 0 | I644: 0 | J644: 5 | K644: 0 | L644: 31 | M644: 0
A645: 87210016 | B645: 7 | C645: 0 | D645: 0 | E645: 45 | F645: 14 | G645: 0 | H645: 14 | I645: 0 | J645: 4 | K645: 0 | L645: 1 | M645: 0
A646: 26210156 | B646: 0 | C646: 0 | D646: 0 | E646: 0 | F646: 25 | G646: 0 | H646: 0 | I646: 0 | J646: 0 | K646: 0 | L646: 22 | M646: 0

Sheet 2022
A1: Region / ALC Code | B1: Jan | C1: Feb | D1: Mar | E1: Apr | F1: May | G1: Jun | H1: Jul | I1: Aug | J1: Sep | K1: Oct | L1: Nov | M1: Dec
A2: 17210059 | B2: 15 | C2: 0 | D2: 15 | E2: 140 | F2: 53 | G2: 0 | H2: 21 | I2: 0 | J2: 19 | K2: 0 | L2: 30 | M2: 19
A3: 32210002 | B3: 29 | C3: 0 | D3: 0 | E3: 116 | F3: 46 | G3: 0 | H3: 34 | I3: 0 | J3: 24 | K3: 0 | L3: 20 | M3: 9
A4: 39210001 | B4: 15 | C4: 0 | D4: 0 | E4: 91 | F4: 17 | G4: 0 | H4: 12 | I4: 0 | J4: 6 | K4: 0 | L4: 6 | M4: 1
A5: 57210018 | B5: 24 | C5: 0 | D5: 13 | E5: 107 | F5: 113 | G5: 0 | H5: 22 | I5: 0 | J5: 20 | K5: 0 | L5: 28 | M5: 18
A6: 17210060 | B6: 21 | C6: 0 | D6: 0 | E6: 446 | F6: 55 | G6: 0 | H6: 44 | I6: 0 | J6: 23 | K6: 0 | L6: 40 | M6: 30
A7: 13210003 | B7: 11 | C7: 0 | D7: 0 | E7: 82 | F7: 52 | G7: 0 | H7: 22 | I7: 0 | J7: 0 | K7: 0 | L7: 25 | M7: 2
A8: 37210001 | B8: 23 | C8: 0 | D8: 5 | E8: 65 | F8: 33 | G8: 0 | H8: 22 | I8: 0 | J8: 21 | K8: 0 | L8: 35 | M8: 13
A9: 34210010 | B9: 52 | C9: 0 | D9: 0 | E9: 59 | F9: 18 | G9: 0 | H9: 29 | I9: 0 | J9: 9 | K9: 0 | L9: 16 | M9: 84
A10: 15210008 | B10: 38 | C10: 0 | D10: 0 | E10: 29 | F10: 24 | G10: 0 | H10: 0 | I10: 0 | J10: 21 | K10: 0 | L10: 34 | M10: 19
A11: 78210122 | B11: 9 | C11: 0 | D11: 9 | E11: 20 | F11: 4 | G11: 0 | H11: 19 | I11: 0 | J11: 7 | K11: 0 | L11: 31 | M11: 4
A12: 78210188 | B12: 8 | C12: 0 | D12: 0 | E12: 25 | F12: 5 | G12: 0 | H12: 6 | I12: 0 | J12: 18 | K12: 0 | L12: 41 | M12: 0
A13: 52210005 | B13: 38 | C13: 0 | D13: 0 | E13: 216 | F13: 55 | G13: 0 | H13: 16 | I13: 0 | J13: 25 | K13: 0 | L13: 15 | M13: 10
... A610: 32210285 | B610: 0 | C610: 0 | D610: 0 | E610: 0 | F610: 6 | G610: 0 | H610: 10 | I610: 0 | J610: 0 | K610: 0 | L610: 37 | M610: 0
A611: 1J210310 | B611: 10 | C611: 0 | D611: 0 | E611: 86 | F611: 29 | G611: 0 | H611: 9 | I611: 0 | J611: 20 | K611: 0 | L611: 13 | M611: 8
A612: 52210297 | B612: 30 | C612: 0 | D612: 5 | E612: 46 | F612: 38 | G612: 0 | H612: 45 | I612: 0 | J612: 12 | K612: 0 | L612: 11 | M612: 6
A613: 87210025 | B613: 13 | C613: 0 | D613: 6 | E613: 21 | F613: 10 | G613: 0 | H613: 5 | I613: 0 | J613: 0 | K613: 0 | L613: 0 | M613: 13
A614: 87210016 | B614: 0 | C614: 0 | D614: 0 | E614: 41 | F614: 11 | G614: 0 | H614: 12 | I614: 0 | J614: 1 | K614: 0 | L614: 7 | M614: 3
A615: 52210305 | B615: 0 | C615: 0 | D615: 0 | E615: 0 | F615: 0 | G615: 0 | H615: 0 | I615: 0 | J615: 0 | K615: 0 | L615: 0 | M615: 10
A616: 87210034 | B616: 0 | C616: 0 | D616: 0 | E616: 0 | F616: 0 | G616: 0 | H616: 0 | I616: 0 | J616: 0 | K616: 0 | L616: 0 | M616: 0
A617: 77210065 | B617: 0 | C617: 0 | D617: 0 | E617: 0 | F617: 0 | G617: 0 | H617: 0 | I617: 0 | J617: 0 | K617: 0 | L617: 0 | M617: 0
A618: 77210077 | B618: 0 | C618: 0 | D618: 0 | E618: 0 | F618: 0 | G618: 0 | H618: 0 | I618: 0 | J618: 0 | K618: 0 | L618: 0 | M618: 0
A619: 77210078 | B619: 0 | C619: 0 | D619: 0 | E619: 0 | F619: 0 | G619: 0 | H619: 0 | I619: 0 | J619: 0 | K619: 0 | L619: 0 | M619: 0
A620: 87210035 | B620: 0 | C620: 0 | D620: 0 | E620: 0 | F620: 0 | G620: 0 | H620: 0 | I620: 0 | J620: 0 | K620: 0 | L620: 0 | M620: 1
A621: 87210039 | B621: 0 | C621: 0 | D621: 0 | E621: 0 | F621: 0 | G621: 0 | H621: 0 | I621: 0 | J621: 0 | K621: 0 | L621: 0 | M621: 0
A622: 26210163 | B622: 0 | C622: 0 | D622: 0 | E622: 0 | F622: 0 | G622: 0 | H622: 0 | I622: 0 | J622: 0 | K622: 0 | L622: 0 | M622: 23
A623: 1J210314 | B623: 0 | C623: 0 | D623: 0 | E623: 0 | F623: 0 | G623: 0 | H623: 0 | I623: 0 | J623: 0 | K623: 0 | L623: 0 | M623: 3
A624: 46210326 | B624: 0 | C624: 0 | D624: 0 | E624: 0 | F624: 0 | G624: 0 | H624: 0 | I624: 0 | J624: 0 | K624: 0 | L624: 0 | M624: 51
A625: 23210344 | B625: 0 | C625: 0 | D625: 0 | E625: 0 | F625: 0 | G625: 0 | H625: 0 | I625: 0 | J625: 0 | K625: 0 | L625: 0 | M625: 11
A626: 77210066 | B626: 0 | C626: 0 | D626: 0 | E626: 0 | F626: 0 | G626: 0 | H626: 0 | I626: 0 | J626: 0 | K626: 0 | L626: 0 | M626: 0
A627: 78210747 | B627: 0 | C627: 0 | D627: 0 | E627: 0 | F627: 0 | G627: 0 | H627: 0 | I627: 0 | J627: 0 | K627: 0 | L627: 0 | M627: 1
A628: 52210304 | B628: 0 | C628: 0 | D628: 0 | E628: 0 | F628: 0 | G628: 0 | H628: 0 | I628: 0 | J628: 0 | K628: 0 | L628: 0 | M628: 6
A629: 77210075 | B629: 0 | C629: 0 | D629: 0 | E629: 0 | F629: 0 | G629: 0 | H629: 0 | I629: 0 | J629: 0 | K629: 0 | L629: 0 | M629: 4
A630: 10O210006 | B630: 0 | C630: 0 | D630: 0 | E630: 0 | F630: 0 | G630: 0 | H630: 0 | I630: 0 | J630: 0 | K630: 0 | L630: 0 | M630: 28
A631: 14210709 | B631: 0 | C631: 0 | D631: 0 | E631: 0 | F631: 0 | G631: 0 | H631: 0 | I631: 0 | J631: 0 | K631: 0 | L631: 0 | M631: 2
A632: 32210308 | B632: 0 | C632: 0 | D632: 0 | E632: 0 | F632: 0 | G632: 0 | H632: 0 | I632: 0 | J632: 0 | K632: 0 | L632: 0 | M632: 12
A633: 77210074 | B633: 0 | C633: 0 | D633: 0 | E633: 0 | F633: 0 | G633: 0 | H633: 0 | I633: 0 | J633: 0 | K633: 0 | L633: 0 | M633: 0
A634: 16210498 | B634: 0 | C634: 0 | D634: 0 | E634: 0 | F634: 0 | G634: 0 | H634: 0 | I634: 0 | J634: 0 | K634: 0 | L634: 0 | M634: 1
A635: 46210314 | B635: 0 | C635: 0 | D635: 0 | E635: 0 | F635: 0 | G635: 0 | H635: 0 | I635: 0 | J635: 0 | K635: 0 | L635: 0 | M635: 13
A636: 14210713 | B636: 0 | C636: 0 | D636: 0 | E636: 0 | F636: 0 | G636: 0 | H636: 0 | I636: 0 | J636: 0 | K636: 0 | L636: 0 | M636: 19
...

Sheet 2023
A1: Region / ALC Code | B1: Jan | C1: Feb | D1: Mar | E1: Apr | F1: May | G1: Jun | H1: Jul | I1: Aug | J1: Sep | K1: Oct | L1: Nov | M1: Dec
A2: 17210059 | B2: 0 | C2: 40 | D2: 0 | E2: 166 | F2: 0 | G2: 0 | H2: 20 | I2: 27 | J2: 0 | K2: 0 | L2: 0 | M2: 0
A3: 32210002 | B3: 0 | C3: 14 | D3: 0 | E3: 126 | F3: 0 | G3: 7 | H3: 2 | I3: 5 | J3: 0 | K3: 0 | L3: 0 | M3: 0
A4: 39210001 | B4: 0 | C4: 26 | D4: 0 | E4: 57 | F4: 0 | G4: 0 | H4: 12 | I4: 10 | J4: 0 | K4: 0 | L4: 0 | M4: 0
A5: 57210018 | B5: 0 | C5: 22 | D5: 0 | E5: 163 | F5: 0 | G5: 15 | H5: 7 | I5: 11 | J5: 0 | K5: 0 | L5: 0 | M5: 0
A6: 17210060 | B6: 0 | C6: 0 | D6: 0 | E6: 555 | F6: 0 | G6: 0 | H6: 38 | I6: 33 | J6: 0 | K6: 0 | L6: 0 | M6: 0
A7: 13210003 | B7: 0 | C7: 25 | D7: 0 | E7: 59 | F7: 0 | G7: 2 | H7: 1 | I7: 0 | J7: 0 | K7: 0 | L7: 0 | M7: 0
A8: 37210001 | B8: 0 | C8: 46 | D8: 0 | E8: 88 | F8: 0 | G8: 12 | H8: 7 | I8: 13 | J8: 0 | K8: 0 | L8: 0 | M8: 0
A9: 34210010 | B9: 0 | C9: 43 | D9: 0 | E9: 67 | F9: 0 | G9: 0 | H9: 28 | I9: 9 | J9: 0 | K9: 0 | L9: 0 | M9: 0
A10: 15210008 | B10: 0 | C10: 0 | D10: 0 | E10: 43 | F10: 0 | G10: 0 | H10: 27 | I10: 0 | J10: 0 | K10: 0 | L10: 0 | M10: 0
A11: 78210122 | B11: 0 | C11: 5 | D11: 0 | E11: 22 | F11: 0 | G11: 12 | H11: 3 | I11: 8 | J11: 0 | K11: 0 | L11: 0 | M11: 0
A12: 78210188 | B12: 0 | C12: 22 | D12: 0 | E12: 49 | F12: 0 | G12: 0 | H12: 22 | I12: 20 | J12: 0 | K12: 0 | L12: 0 | M12: 0
A13: 52210005 | B13: 0 | C13: 80 | D13: 0 | E13: 92 | F13: 0 | G13: 11 | H13: 13 | I13: 24 | J13: 0 | K13: 0 | L13: 0 | M13: 0
... A585: 32210285 | B585: 0 | C585: 0 | D585: 0 | E585: 46 | F585: 0 | G585: 0 | H585: 0 | I585: 0 | J585: 0 | K585: 0 | L585: 0 | M585: 0
A586: 1J210310 | B586: 0 | C586: 60 | D586: 0 | E586: 56 | F586: 0 | G586: 0 | H586: 19 | I586: 9 | J586: 0 | K586: 0 | L586: 0 | M586: 0
A587: 52210297 | B587: 0 | C587: 27 | D587: 0 | E587: 26 | F587: 0 | G587: 11 | H587: 0 | I587: 8 | J587: 0 | K587: 0 | L587: 0 | M587: 0
A588: 87210025 | B588: 0 | C588: 0 | D588: 0 | E588: 37 | F588: 0 | G588: 11 | H588: 5 | I588: 0 | J588: 0 | K588: 0 | L588: 0 | M588: 0
A589: 87210016 | B589: 0 | C589: 13 | D589: 0 | E589: 75 | F589: 0 | G589: 14 | H589: 2 | I589: 12 | J589: 0 | K589: 0 | L589: 0 | M589: 0
A590: 52210305 | B590: 0 | C590: 50 | D590: 0 | E590: 57 | F590: 0 | G590: 0 | H590: 0 | I590: 0 | J590: 0 | K590: 0 | L590: 0 | M590: 0
A591: 87210034 | B591: 0 | C591: 0 | D591: 0 | E591: 75 | F591: 0 | G591: 5 | H591: 3 | I591: 3 | J591: 0 | K591: 0 | L591: 0 | M591: 0
A592: 77210065 | B592: 0 | C592: 15 | D592: 0 | E592: 97 | F592: 0 | G592: 7 | H592: 8 | I592: 66 | J592: 0 | K592: 0 | L592: 0 | M592: 0
A593: 77210077 | B593: 0 | C593: 0 | D593: 0 | E593: 50 | F593: 0 | G593: 0 | H593: 2 | I593: 2 | J593: 0 | K593: 0 | L593: 0 | M593: 0
A594: 77210078 | B594: 0 | C594: 0 | D594: 0 | E594: 48 | F594: 0 | G594: 0 | H594: 3 | I594: 0 | J594: 0 | K594: 0 | L594: 0 | M594: 0
A595: 87210035 | B595: 0 | C595: 4 | D595: 0 | E595: 34 | F595: 0 | G595: 11 | H595: 3 | I595: 9 | J595: 0 | K595: 0 | L595: 0 | M595: 0
A596: 87210039 | B596: 0 | C596: 0 | D596: 0 | E596: 26 | F596: 0 | G596: 3 | H596: 0 | I596: 10 | J596: 0 | K596: 0 | L596: 0 | M596: 0
A597: 26210163 | B597: 0 | C597: 15 | D597: 0 | E597: 59 | F597: 0 | G597: 9 | H597: 0 | I597: 11 | J597: 0 | K597: 0 | L597: 0 | M597: 0
A598: 1J210314 | B598: 0 | C598: 20 | D598: 0 | E598: 97 | F598: 0 | G598: 0 | H598: 12 | I598: 0 | J598: 0 | K598: 0 | L598: 0 | M598: 0
A599: 46210326 | B599: 0 | C599: 22 | D599: 0 | E599: 70 | F599: 0 | G599: 0 | H599: 2 | I599: 0 | J599: 0 | K599: 0 | L599: 0 | M599: 0
A600: 88210031 | B600: 0 | C600: 2 | D600: 0 | E600: 23 | F600: 0 | G600: 0 | H600: 4 | I600: 15 | J600: 0 | K600: 0 | L600: 0 | M600: 0
A601: 23210344 | B601: 0 | C601: 8 | D601: 0 | E601: 76 | F601: 0 | G601: 0 | H601: 6 | I601: 7 | J601: 0 | K601: 0 | L601: 0 | M601: 0
A602: 77210066 | B602: 0 | C602: 0 | D602: 0 | E602: 42 | F602: 0 | G602: 8 | H602: 2 | I602: 4 | J602: 0 | K602: 0 | L602: 0 | M602: 0
A603: 78210747 | B603: 0 | C603: 11 | D603: 0 | E603: 28 | F603: 0 | G603: 4 | H603: 2 | I603: 3 | J603: 0 | K603: 0 | L603: 0 | M603: 0
A604: 52210304 | B604: 0 | C604: 15 | D604: 0 | E604: 58 | F604: 0 | G604: 9 | H604: 11 | I604: 7 | J604: 0 | K604: 0 | L604: 0 | M604: 0
A605: 77210075 | B605: 0 | C605: 9 | D605: 0 | E605: 57 | F605: 0 | G605: 0 | H605: 12 | I605: 15 | J605: 0 | K605: 0 | L605: 0 | M605: 0
A606: 10O210006 | B606: 0 | C606: 48 | D606: 0 | E606: 90 | F606: 0 | G606: 0 | H606: 18 | I606: 12 | J606: 0 | K606: 0 | L606: 0 | M606: 0
A607: 14210709 | B607: 0 | C607: 6 | D607: 0 | E607: 4 | F607: 0 | G607: 3 | H607: 1 | I607: 3 | J607: 0 | K607: 0 | L607: 0 | M607: 0
A608: 32210308 | B608: 0 | C608: 0 | D608: 0 | E608: 37 | F608: 0 | G608: 11 | H608: 0 | I608: 31 | J608: 0 | K608: 0 | L608: 0 | M608: 0
A609: 77210074 | B609: 0 | C609: 7 | D609: 0 | E609: 20 | F609: 0 | G609: 4 | H609: 1 | I609: 15 | J609: 0 | K609: 3 | L609: 0 | M609: 0
A610: 16210498 | B610: 0 | C610: 3 | D610: 0 | E610: 13 | F610: 0 | G610: 2 | H610: 0 | I610: 9 | J610: 0 | K610: 0 | L610: 0 | M610: 0
A611: 46210314 | B611: 0 | C611: 24 | D611: 0 | E611: 60 | F611: 0 | G611: 11 | H611: 11 | I611: 16 | J611: 0 | K611: 0 | L611: 0 | M611: 0
...

Sheet Sheet5
A3: Row Labels | B3: Count of Jan | C3: Count of Nov | D3: Count of Dec | E3: Count of Oct | F3: Count of Sep | G3: Count of Jul | H3: Count of Jun | I3: Count of Feb | J3: Count of Aug | K3: Count of May | L3: Count of Apr | M3: Count of Mar
A4: Ahmednagar | B4: 20 | C4: 20 | D4: 20 | E4: 20 | F4: 20 | G4: 20 | H4: 20 | I4: 20 | J4: 20 | K4: 20 | L4: 20 | M4: 20
A5: Akola | B5: 15 | C5: 15 | D5: 15 | E5: 15 | F5: 15 | G5: 15 | H5: 15 | I5: 15 | J5: 15 | K5: 15 | L5: 15 | M5: 15
A6: Amravati | B6: 43 | C6: 43 | D6: 43 | E6: 43 | F6: 43 | G6: 43 | H6: 43 | I6: 43 | J6: 43 | K6: 43 | L6: 43 | M6: 43
A7: Aurangabad | B7: 29 | C7: 29 | D7: 29 | E7: 29 | F7: 29 | G7: 29 | H7: 29 | I7: 29 | J7: 29 | K7: 29 | L7: 29 | M7: 29
A8: Beed | B8: 15 | C8: 15 | D8: 15 | E8: 15 | F8: 15 | G8: 15 | H8: 15 | I8: 15 | J8: 15 | K8: 15 | L8: 15 | M8: 15
A9: Bhandara | B9: 13 | C9: 13 | D9: 13 | E9: 13 | F9: 13 | G9: 13 | H9: 13 | I9: 13 | J9: 13 | K9: 13 | L9: 13 | M9: 13
A10: Buldhana | B10: 19 | C10: 19 | D10: 19 | E10: 19 | F10: 19 | G10: 19 | H10: 19 | I10: 19 | J10: 19 | K10: 19 | L10: 19 | M10: 19
A11: Chandrapur | B11: 21 | C11: 21 | D11: 21 | E11: 21 | F11: 21 | G11: 21 | H11: 21 | I11: 21 | J11: 21 | K11: 21 | L11: 21 | M11: 21
A12: Dhule | B12: 13 | C12: 13 | D12: 13 | E12: 13 | F12: 13 | G12: 13 | H12: 13 | I12: 13 | J12: 13 | K12: 13 | L12: 13 | M12: 13
A13: Gadchiroli | B13: 4 | C13: 4 | D13: 4 | E13: 4 | F13: 4 | G13: 4 | H13: 4 | I13: 4 | J13: 4 | K13: 4 | L13: 4 | M13: 4
A14: Gondiya | B14: 11 | C14: 11 | D14: 11 | E14: 11 | F14: 11 | G14: 11 | H14: 11 | I14: 11 | J14: 11 | K14: 11 | L14: 11 | M14: 11
A15: Hingoli | B15: 3 | C15: 3 | D15: 3 | E15: 3 | F15: 3 | G15: 3 | H15: 3 | I15: 3 | J15: 3 | K15: 3 | L15: 3 | M15: 3
... A41: Grand Total | B41: 635 | C41: 635 | D41: 635 | E41: 635 | F41: 635 | G41: 635 | H41: 635 | I41: 635 | J41: 635 | K41: 635 | L41: 635 | M41: 635

Sheet MASTER DATA
A1: Sr.No. | B1: Center Code | C1: Center Name | D1: Center Category | E1: Area Type | F1: City | G1: Taluka | H1: District | I1: State | J1: Address | K1: Mobile | L1: Phone | M1: Email | N1: DM | O1: Jan | P1: Feb | Q1: Mar | R1: Apr | S1: May | T1: Jun | U1: Jul | V1: Aug | W1: Sep | X1: Oct | Y1: Nov | Z1: Dec
A2: 1 | B2: 17210060 | C2: Shubham Computer Education | D2: MS-CIT Renewed | E2: Urban | F2: Sangamner | G2: Sangamner | H2: Ahmednagar | I2: Maharashtra | J2: 5,FIRST FLOOR NAGARPALIKA SHOPPING CENTER NEW NAGAR ROAD, SANGAMNERSANGAMNER-422605 | K2: 9822056842 | L2: 02425-226981 | M2: 17210060@mkcl.org | N2: Sambhaji Tagad | O2: =VLOOKUP($B2,Sheet4!$A$1:$M$4092,MATCH('MASTER DATA'!O$1,Sheet4!$A$1:$M$1,0),0) -> 275 | P2: =VLOOKUP($B2,Sheet4!$A$1:$M$4092,MATCH('MASTER DATA'!P$1,Sheet4!$A$1:$M$1,0),0) -> 28 | Q2: =VLOOKUP($B2,Sheet4!$A$1:$M$4092,MATCH('MASTER DATA'!Q$1,Sheet4!$A$1:$M$1,0),0) -> 37 | R2: =VLOOKUP($B2,Sheet4!$A$1:$M$4092,MATCH('MASTER DATA'!R$1,Sheet4!$A$1:$M$1,0),0) -> 2154 | S2: =VLOOKUP($B2,Sheet4!$A$1:$M$4092,MATCH('MASTER DATA'!S$1,Sheet4!$A$1:$M$1,0),0) -> 438 | T2: =VLOOKUP($B2,Sheet4!$A$1:$M$4092,MATCH('MASTER DATA'!T$1,Sheet4!$A$1:$M$1,0),0) -> 35 | U2: =VLOOKUP($B2,Sheet4!$A$1:$M$4092,MATCH('MASTER DATA'!U$1,Sheet4!$A$1:$M$1,0),0) -> 177 | V2: =VLOOKUP($B2,Sheet4!$A$1:$M$4092,MATCH('MASTER DATA'!V$1,Sheet4!$A$1:$M$1,0),0) -> 84 | ... Z2: =VLOOKUP($B2,Sheet4!$A$1:$M$4092,MATCH('MASTER DATA'!Z$1,Sheet4!$A$1:$M$1,0),0) -> 44
A3: 2 | B3: 17210010 | C3: Ideal Computers | D3: MS-CIT Renewed | E3: Urban | F3: Sangamner | G3: Sangamner | H3: Ahmednagar | I3: Maharashtra | J3: GANESH NAGAR, RIDHI SIDHI APPT. NEAR GANESH MANDIR, SANGAMNERSANGAMNER-422605 | K3: 9890179748 | L3: 02425-226748 | M3: 17210010@mkcl.org | N3: Sambhaji Tagad | O3: =VLOOKUP($B3,Sheet4!$A$1:$M$4092,MATCH('MASTER DATA'!O$1,Sheet4!$A$1:$M$1,0),0) -> 51 | P3: =VLOOKUP($B3,Sheet4!$A$1:$M$4092,MATCH('MASTER DATA'!P$1,Sheet4!$A$1:$M$1,0),0) -> 20 | Q3: =VLOOKUP($B3,Sheet4!$A$1:$M$4092,MATCH('MASTER DATA'!Q$1,Sheet4!$A$1:$M$1,0),0) -> 111 | R3: =VLOOKUP($B3,Sheet4!$A$1:$M$4092,MATCH('MASTER DATA'!R$1,Sheet4!$A$1:$M$1,0),0) -> 779 | S3: =VLOOKUP($B3,Sheet4!$A$1:$M$4092,MATCH('MASTER DATA'!S$1,Sheet4!$A$1:$M$1,0),0) -> 207 | T3: =VLOOKUP($B3,Sheet4!$A$1:$M$4092,MATCH('MASTER DATA'!T$1,Sheet4!$A$1:$M$1,0),0) -> 5 | U3: =VLOOKUP($B3,Sheet4!$A$1:$M$4092,MATCH('MASTER DATA'!U$1,Sheet4!$A$1:$M$1,0),0) -> 122 | V3: =VLOOKUP($B3,Sheet4!$A$1:$M$4092,MATCH('MASTER DATA'!V$1,Sheet4!$A$1:$M$1,0),0) -> 61 | ... Z3: =VLOOKUP($B3,Sheet4!$A$1:$M$4092,MATCH('MASTER DATA'!Z$1,Sheet4!$A$1:$M$1,0),0) -> 33
A4: 3 | B4: 17210034 | C4: Cybernet Systems | D4: MS-CIT Renewed | E4: Urban | F4: Kopargaon | G4: Kopargaon | H4: Ahmednagar | I4: Maharashtra | J4: 1ST FLOOR, ABOVE SWASTIK MEDICAL, OPP. OLD MUNICIPAL CORPORATION BUILDING, BHAGWAN MAHAVIR PATH, KOPARGAONKOPARGAON-423601 | K4: 9370332866 | L4: 02423-222366 | M4: 17210034@mkcl.org | N4: Sambhaji Tagad | O4: =VLOOKUP($B4,Sheet4!$A$1:$M$4092,MATCH('MASTER DATA'!O$1,Sheet4!$A$1:$M$1,0),0) -> 99 | P4: =VLOOKUP($B4,Sheet4!$A$1:$M$4092,MATCH('MASTER DATA'!P$1,Sheet4!$A$1:$M$1,0),0) -> 33 | Q4: =VLOOKUP($B4,Sheet4!$A$1:$M$4092,MATCH('MASTER DATA'!Q$1,Sheet4!$A$1:$M$1,0),0) -> 156 | R4: =VLOOKUP($B4,Sheet4!$A$1:$M$4092,MATCH('MASTER DATA'!R$1,Sheet4!$A$1:$M$1,0),0) -> 1079 | S4: =VLOOKUP($B4,Sheet4!$A$1:$M$4092,MATCH('MASTER DATA'!S$1,Sheet4!$A$1:$M$1,0),0) -> 301 | T4: =VLOOKUP($B4,Sheet4!$A$1:$M$4092,MATCH('MASTER DATA'!T$1,Sheet4!$A$1:$M$1,0),0) -> 34 | U4: =VLOOKUP($B4,Sheet4!$A$1:$M$4092,MATCH('MASTER DATA'!U$1,Sheet4!$A$1:$M$1,0),0) -> 102 | V4: =VLOOKUP($B4,Sheet4!$A$1:$M$4092,MATCH('MASTER DATA'!V$1,Sheet4!$A$1:$M$1,0),0) -> 59 | ... Z4: =VLOOKUP($B4,Sheet4!$A$1:$M$4092,MATCH('MASTER DATA'!Z$1,Sheet4!$A$1:$M$1,0),0) -> 16
A5: 4 | B5: 17210059 | C5: Sai Computer Education | D5: MS-CIT Renewed | E5: Urban | F5: Rahuri | G5: Rahuri | H5: Ahmednagar | I5: Maharashtra | J5: SAI COMPUTER EDUCATION, NEAR M.P SOCIETY,MARKET YARDRAHURI-413705 | K5: 9371761331 | L5: 02426-232205 | M5: 17210059@mkcl.org | N5: Sambhaji Tagad | O5: =VLOOKUP($B5,Sheet4!$A$1:$M$4092,MATCH('MASTER DATA'!O$1,Sheet4!$A$1:$M$1,0),0) -> 50 | P5: =VLOOKUP($B5,Sheet4!$A$1:$M$4092,MATCH('MASTER DATA'!P$1,Sheet4!$A$1:$M$1,0),0) -> 49 | Q5: =VLOOKUP($B5,Sheet4!$A$1:$M$4092,MATCH('MASTER DATA'!Q$1,Sheet4!$A$1:$M$1,0),0) -> 96 | R5: =VLOOKUP($B5,Sheet4!$A$1:$M$4092,MATCH('MASTER DATA'!R$1,Sheet4!$A$1:$M$1,0),0) -> 506 | S5: =VLOOKUP($B5,Sheet4!$A$1:$M$4092,MATCH('MASTER DATA'!S$1,Sheet4!$A$1:$M$1,0),0) -> 165 | T5: =VLOOKUP($B5,Sheet4!$A$1:$M$4092,MATCH('MASTER DATA'!T$1,Sheet4!$A$1:$M$1,0),0) -> 11 | U5: =VLOOKUP($B5,Sheet4!$A$1:$M$4092,MATCH('MASTER DATA'!U$1,Sheet4!$A$1:$M$1,0),0) -> 82 | V5: =VLOOKUP($B5,Sheet4!$A$1:$M$4092,MATCH('MASTER DATA'!V$1,Sheet4!$A$1:$M$1,0),0) -> 53 | ... Z5: =VLOOKUP($B5,Sheet4!$A$1:$M$4092,MATCH('MASTER DATA'!Z$1,Sheet4!$A$1:$M$1,0),0) -> 22
A6: 5 | B6: 17210096 | C6: Unitech Computer Education | D6: MS-CIT Renewed | E6: Rural | F6: Ashvi Kd. | G6: Sangamner | H6: Ahmednagar | I6: Maharashtra | J6: ASHVI KHURDASHVI KD.-413738 | K6: 9503984929 | L6: 02425-241491 | M6: 17210096@mkcl.org | N6: Sambhaji Tagad | O6: =VLOOKUP($B6,Sheet4!$A$1:$M$4092,MATCH('MASTER DATA'!O$1,Sheet4!$A$1:$M$1,0),0) -> 0 | P6: =VLOOKUP($B6,Sheet4!$A$1:$M$4092,MATCH('MASTER DATA'!P$1,Sheet4!$A$1:$M$1,0),0) -> 0 | Q6: =VLOOKUP($B6,Sheet4!$A$1:$M$4092,MATCH('MASTER DATA'!Q$1,Sheet4!$A$1:$M$1,0),0) -> 0 | R6: =VLOOKUP($B6,Sheet4!$A$1:$M$4092,MATCH('MASTER DATA'!R$1,Sheet4!$A$1:$M$1,0),0) -> 124 | S6: =VLOOKUP($B6,Sheet4!$A$1:$M$4092,MATCH('MASTER DATA'!S$1,Sheet4!$A$1:$M$1,0),0) -> 135 | T6: =VLOOKUP($B6,Sheet4!$A$1:$M$4092,MATCH('MASTER DATA'!T$1,Sheet4!$A$1:$M$1,0),0) -> 0 | U6: =VLOOKUP($B6,Sheet4!$A$1:$M$4092,MATCH('MASTER DATA'!U$1,Sheet4!$A$1:$M$1,0),0) -> 39 | V6: =VLOOKUP($B6,Sheet4!$A$1:$M$4092,MATCH('MASTER DATA'!V$1,Sheet4!$A$1:$M$1,0),0) -> 3 | ... Z6: =VLOOKUP($B6,Sheet4!$A$1:$M$4092,MATCH('MASTER DATA'!Z$1,Sheet4!$A$1:$M$1,0),0) -> 0
A7: 6 | B7: 17210107 | C7: Kalpesh Computer Education | D7: MS-CIT Renewed | E7: Rural | F7: Sangamner | G7: Sangamner | H7: Ahmednagar | I7: Maharashtra | J7: NEAR GRAMSACHIVALAY, SAKURSANGAMNER-422622 | K7: 9011711185 | L7: 02425-275043 | M7: 17210107@mkcl.org | N7: Sambhaji Tagad | O7: =VLOOKUP($B7,Sheet4!$A$1:$M$4092,MATCH('MASTER DATA'!O$1,Sheet4!$A$1:$M$1,0),0) -> 48 | P7: =VLOOKUP($B7,Sheet4!$A$1:$M$4092,MATCH('MASTER DATA'!P$1,Sheet4!$A$1:$M$1,0),0) -> 14 | Q7: =VLOOKUP($B7,Sheet4!$A$1:$M$4092,MATCH('MASTER DATA'!Q$1,Sheet4!$A$1:$M$1,0),0) -> 33 | R7: =VLOOKUP($B7,Sheet4!$A$1:$M$4092,MATCH('MASTER DATA'!R$1,Sheet4!$A$1:$M$1,0),0) -> 522 | S7: =VLOOKUP($B7,Sheet4!$A$1:$M$4092,MATCH('MASTER DATA'!S$1,Sheet4!$A$1:$M$1,0),0) -> 442 | T7: =VLOOKUP($B7,Sheet4!$A$1:$M$4092,MATCH('MASTER DATA'!T$1,Sheet4!$A$1:$M$1,0),0) -> 4 | U7: =VLOOKUP($B7,Sheet4!$A$1:$M$4092,MATCH('MASTER DATA'!U$1,Sheet4!$A$1:$M$1,0),0) -> 29 | V7: =VLOOKUP($B7,Sheet4!$A$1:$M$4092,MATCH('MASTER DATA'!V$1,Sheet4!$A$1:$M$1,0),0) -> 19 | ... Z7: =VLOOKUP($B7,Sheet4!$A$1:$M$4092,MATCH('MASTER DATA'!Z$1,Sheet4!$A$1:$M$1,0),0) -> 9
A8: 7 | B8: 17210112 | C8: Vimal Computers | D8: MS-CIT Renewed | E8: Rural | F8: Kolpewadi | G8: Kopargaon | H8: Ahmednagar | I8: Maharashtra | J8: AT. NEAR GAUTAM PUBLIC SCHOOL KOLPEWADI KOPARGAONKOLPEWADI-423602 | K8: 9890684382 | L8: 02423-262179 | M8: 17210112@mkcl.org | N8: Sambhaji Tagad | O8: =VLOOKUP($B8,Sheet4!$A$1:$M$4092,MATCH('MASTER DATA'!O$1,Sheet4!$A$1:$M$1,0),0) -> 50 | P8: =VLOOKUP($B8,Sheet4!$A$1:$M$4092,MATCH('MASTER DATA'!P$1,Sheet4!$A$1:$M$1,0),0) -> 21 | Q8: =VLOOKUP($B8,Sheet4!$A$1:$M$4092,MATCH('MASTER DATA'!Q$1,Sheet4!$A$1:$M$1,0),0) -> 89 | R8: =VLOOKUP($B8,Sheet4!$A$1:$M$4092,MATCH('MASTER DATA'!R$1,Sheet4!$A$1:$M$1,0),0) -> 283 | S8: =VLOOKUP($B8,Sheet4!$A$1:$M$4092,MATCH('MASTER DATA'!S$1,Sheet4!$A$1:$M$1,0),0) -> 24 | T8: =VLOOKUP($B8,Sheet4!$A$1:$M$4092,MATCH('MASTER DATA'!T$1,Sheet4!$A$1:$M$1,0),0) -> 8 | U8: =VLOOKUP($B8,Sheet4!$A$1:$M$4092,MATCH('MASTER DATA'!U$1,Sheet4!$A$1:$M$1,0),0) -> 15 | V8: =VLOOKUP($B8,Sheet4!$A$1:$M$4092,MATCH('MASTER DATA'!V$1,Sheet4!$A$1:$M$1,0),0) -> 11 | ... Z8: =VLOOKUP($B8,Sheet4!$A$1:$M$4092,MATCH('MASTER DATA'!Z$1,Sheet4!$A$1:$M$1,0),0) -> 8
A9: 8 | B9: 17210149 | C9: Venus Computer | D9: MS-CIT Renewed | E9: Urban | F9: Sangamner | G9: Sangamner | H9: Ahmednagar | I9: Maharashtra | J9: ABOVE DR. HEMANT SHINDE SAI SONOGRAPHY, 1ST FLOOR, SAI COMPLEX, NEAR POST OFFICE, NEW NAGAR ROAD, SANGAMNER - 422605 TEL 02425 - 223418 SANGAMNER-422605 | K9: 9822041222 | L9: 02425-223418 | M9: 17210149@mkcl.org | N9: Sambhaji Tagad | O9: =VLOOKUP($B9,Sheet4!$A$1:$M$4092,MATCH('MASTER DATA'!O$1,Sheet4!$A$1:$M$1,0),0) -> 47 | P9: =VLOOKUP($B9,Sheet4!$A$1:$M$4092,MATCH('MASTER DATA'!P$1,Sheet4!$A$1:$M$1,0),0) -> 28 | Q9: =VLOOKUP($B9,Sheet4!$A$1:$M$4092,MATCH('MASTER DATA'!Q$1,Sheet4!$A$1:$M$1,0),0) -> 91 | R9: =VLOOKUP($B9,Sheet4!$A$1:$M$4092,MATCH('MASTER DATA'!R$1,Sheet4!$A$1:$M$1,0),0) -> 301 | S9: =VLOOKUP($B9,Sheet4!$A$1:$M$4092,MATCH('MASTER DATA'!S$1,Sheet4!$A$1:$M$1,0),0) -> 186 | T9: =VLOOKUP($B9,Sheet4!$A$1:$M$4092,MATCH('MASTER DATA'!T$1,Sheet4!$A$1:$M$1,0),0) -> 24 | U9: =VLOOKUP($B9,Sheet4!$A$1:$M$4092,MATCH('MASTER DATA'!U$1,Sheet4!$A$1:$M$1,0),0) -> 45 | V9: =VLOOKUP($B9,Sheet4!$A$1:$M$4092,MATCH('MASTER DATA'!V$1,Sheet4!$A$1:$M$1,0),0) -> 15 | ... Z9: =VLOOKUP($B9,Sheet4!$A$1:$M$4092,MATCH('MASTER DATA'!Z$1,Sheet4!$A$1:$M$1,0),0) -> 1
A10: 9 | B10: 17210161 | C10: Shree Computer | D10: MS-CIT Renewed | E10: Rural | F10: Belwandi | G10: Shrigonda | H10: Ahmednagar | I10: Maharashtra | J10: PLOT NO 842/2/20, SHIVALAYA APARTMENT, SHREENATH NAGAR BELWANDI BK BELWANDI-413702 | K10: 9850666966 | L10: 02487-250075 | M10: 17210161@mkcl.org | N10: Sambhaji Tagad | O10: =VLOOKUP($B10,Sheet4!$A$1:$M$4092,MATCH('MASTER DATA'!O$1,Sheet4!$A$1:$M$1,0),0) -> 12 | P10: =VLOOKUP($B10,Sheet4!$A$1:$M$4092,MATCH('MASTER DATA'!P$1,Sheet4!$A$1:$M$1,0),0) -> 1 | Q10: =VLOOKUP($B10,Sheet4!$A$1:$M$4092,MATCH('MASTER DATA'!Q$1,Sheet4!$A$1:$M$1,0),0) -> 118 | R10: =VLOOKUP($B10,Sheet4!$A$1:$M$4092,MATCH('MASTER DATA'!R$1,Sheet4!$A$1:$M$1,0),0) -> 821 | S10: =VLOOKUP($B10,Sheet4!$A$1:$M$4092,MATCH('MASTER DATA'!S$1,Sheet4!$A$1:$M$1,0),0) -> 60 | T10: =VLOOKUP($B10,Sheet4!$A$1:$M$4092,MATCH('MASTER DATA'!T$1,Sheet4!$A$1:$M$1,0),0) -> 4 | U10: =VLOOKUP($B10,Sheet4!$A$1:$M$4092,MATCH('MASTER DATA'!U$1,Sheet4!$A$1:$M$1,0),0) -> 27 | V10: =VLOOKUP($B10,Sheet4!$A$1:$M$4092,MATCH('MASTER DATA'!V$1,Sheet4!$A$1:$M$1,0),0) -> 8 | ... Z10: =VLOOKUP($B10,Sheet4!$A$1:$M$4092,MATCH('MASTER DATA'!Z$1,Sheet4!$A$1:$M$1,0),0) -> 3
A11: 10 | B11: 17210168 | C11: Unique Computer Education | D11: MS-CIT Renewed | E11: Rural | F11: Kolpewadi | G11: Kopargaon | H11: Ahmednagar | I11: Maharashtra | J11: A/P - KOLPEWADIKOLPEWADI-423602 | K11: 9421560411 | L11: 02423-261411 | M11: 17210168@mkcl.org | N11: Sambhaji Tagad | O11: =VLOOKUP($B11,Sheet4!$A$1:$M$4092,MATCH('MASTER DATA'!O$1,Sheet4!$A$1:$M$1,0),0) -> 14 | P11: =VLOOKUP($B11,Sheet4!$A$1:$M$4092,MATCH('MASTER DATA'!P$1,Sheet4!$A$1:$M$1,0),0) -> 26 | Q11: =VLOOKUP($B11,Sheet4!$A$1:$M$4092,MATCH('MASTER DATA'!Q$1,Sheet4!$A$1:$M$1,0),0) -> 87 | R11: =VLOOKUP($B11,Sheet4!$A$1:$M$4092,MATCH('MASTER DATA'!R$1,Sheet4!$A$1:$M$1,0),0) -> 597 | S11: =VLOOKUP($B11,Sheet4!$A$1:$M$4092,MATCH('MASTER DATA'!S$1,Sheet4!$A$1:$M$1,0),0) -> 51 | T11: =VLOOKUP($B11,Sheet4!$A$1:$M$4092,MATCH('MASTER DATA'!T$1,Sheet4!$A$1:$M$1,0),0) -> 8 | U11: =VLOOKUP($B11,Sheet4!$A$1:$M$4092,MATCH('MASTER DATA'!U$1,Sheet4!$A$1:$M$1,0),0) -> 34 | V11: =VLOOKUP($B11,Sheet4!$A$1:$M$4092,MATCH('MASTER DATA'!V$1,Sheet4!$A$1:$M$1,0),0) -> 14 | ... Z11: =VLOOKUP($B11,Sheet4!$A$1:$M$4092,MATCH('MASTER DATA'!Z$1,Sheet4!$A$1:$M$1,0),0) -> 4
A12: 11 | B12: 17210234 | C12: Sushil Computer Clasess | D12: MS-CIT Renewed | E12: Urban | F12: Pathardi | G12: Pathardi | H12: Ahmednagar | I12: Maharashtra | J12: NAGAR ROAD, PATHARDI, TAL-PATHARDI, DIST-AHMEDNAGARPATHARDI-414102 | K12: 9423046448 | L12: 02428-221148 | M12: 17210234@mkcl.org | N12: Sambhaji Tagad | O12: =VLOOKUP($B12,Sheet4!$A$1:$M$4092,MATCH('MASTER DATA'!O$1,Sheet4!$A$1:$M$1,0),0) -> 159 | P12: =VLOOKUP($B12,Sheet4!$A$1:$M$4092,MATCH('MASTER DATA'!P$1,Sheet4!$A$1:$M$1,0),0) -> 126 | Q12: =VLOOKUP($B12,Sheet4!$A$1:$M$4092,MATCH('MASTER DATA'!Q$1,Sheet4!$A$1:$M$1,0),0) -> 199 | R12: =VLOOKUP($B12,Sheet4!$A$1:$M$4092,MATCH('MASTER DATA'!R$1,Sheet4!$A$1:$M$1,0),0) -> 459 | S12: =VLOOKUP($B12,Sheet4!$A$1:$M$4092,MATCH('MASTER DATA'!S$1,Sheet4!$A$1:$M$1,0),0) -> 149 | T12: =VLOOKUP($B12,Sheet4!$A$1:$M$4092,MATCH('MASTER DATA'!T$1,Sheet4!$A$1:$M$1,0),0) -> 49 | U12: =VLOOKUP($B12,Sheet4!$A$1:$M$4092,MATCH('MASTER DATA'!U$1,Sheet4!$A$1:$M$1,0),0) -> 182 | V12: =VLOOKUP($B12,Sheet4!$A$1:$M$4092,MATCH('MASTER DATA'!V$1,Sheet4!$A$1:$M$1,0),0) -> 83 | ... Z12: =VLOOKUP($B12,Sheet4!$A$1:$M$4092,MATCH('MASTER DATA'!Z$1,Sheet4!$A$1:$M$1,0),0) -> 63
A13: 12 | B13: 17210273 | C13: SHUBHAM COMPUTERS, NIMON | D13: MS-CIT Renewed | E13: Rural | F13: NIMON | G13: Sangamner | H13: Ahmednagar | I13: Maharashtra | J13: OPP. S.T. STAND, CHAITANYA COMPLEX, LONI-NANDUR ROAD, NIMONNIMON-422611 | K13: 9850448553 | L13: 02425-264111 | M13: 17210273@mkcl.org | N13: Sambhaji Tagad | O13: =VLOOKUP($B13,Sheet4!$A$1:$M$4092,MATCH('MASTER DATA'!O$1,Sheet4!$A$1:$M$1,0),0) -> 13 | P13: =VLOOKUP($B13,Sheet4!$A$1:$M$4092,MATCH('MASTER DATA'!P$1,Sheet4!$A$1:$M$1,0),0) -> 0 | Q13: =VLOOKUP($B13,Sheet4!$A$1:$M$4092,MATCH('MASTER DATA'!Q$1,Sheet4!$A$1:$M$1,0),0) -> 0 | R13: =VLOOKUP($B13,Sheet4!$A$1:$M$4092,MATCH('MASTER DATA'!R$1,Sheet4!$A$1:$M$1,0),0) -> 254 | S13: =VLOOKUP($B13,Sheet4!$A$1:$M$4092,MATCH('MASTER DATA'!S$1,Sheet4!$A$1:$M$1,0),0) -> 61 | T13: =VLOOKUP($B13,Sheet4!$A$1:$M$4092,MATCH('MASTER DATA'!T$1,Sheet4!$A$1:$M$1,0),0) -> 1 | U13: =VLOOKUP($B13,Sheet4!$A$1:$M$4092,MATCH('MASTER DATA'!U$1,Sheet4!$A$1:$M$1,0),0) -> 3 | V13: =VLOOKUP($B13,Sheet4!$A$1:$M$4092,MATCH('MASTER DATA'!V$1,Sheet4!$A$1:$M$1,0),0) -> 4 | ... Z13: =VLOOKUP($B13,Sheet4!$A$1:$M$4092,MATCH('MASTER DATA'!Z$1,Sheet4!$A$1:$M$1,0),0) -> 1
... A152: 151 | B152: 32210285 | C152: VAISHNAVI COMPUTERS DONGAON | D152: MS-CIT NCR-2017 | E152: Rural | F152: MEHKAR | G152: Mehekar | H152: Buldhana | I152: Maharashtra | J152: AREGAON ROAD GJANAN MANDIRA MAGE DONGAON MEHKAR-443303 | K152: 9637153030 | L152: 07268-266509 | M152: 32210285@mkcl.org | N152: Kumar Katare | O152: =VLOOKUP($B152,Sheet4!$A$1:$M$4092,MATCH('MASTER DATA'!O$1,Sheet4!$A$1:$M$1,0),0) -> 0 | P152: =VLOOKUP($B152,Sheet4!$A$1:$M$4092,MATCH('MASTER DATA'!P$1,Sheet4!$A$1:$M$1,0),0) -> 0 | Q152: =VLOOKUP($B152,Sheet4!$A$1:$M$4092,MATCH('MASTER DATA'!Q$1,Sheet4!$A$1:$M$1,0),0) -> 0 | R152: =VLOOKUP($B152,Sheet4!$A$1:$M$4092,MATCH('MASTER DATA'!R$1,Sheet4!$A$1:$M$1,0),0) -> 46 | S152: =VLOOKUP($B152,Sheet4!$A$1:$M$4092,MATCH('MASTER DATA'!S$1,Sheet4!$A$1:$M$1,0),0) -> 21 | T152: =VLOOKUP($B152,Sheet4!$A$1:$M$4092,MATCH('MASTER DATA'!T$1,Sheet4!$A$1:$M$1,0),0) -> 0 | U152: =VLOOKUP($B152,Sheet4!$A$1:$M$4092,MATCH('MASTER DATA'!U$1,Sheet4!$A$1:$M$1,0),0) -> 10 | V152: =VLOOKUP($B152,Sheet4!$A$1:$M$4092,MATCH('MASTER DATA'!V$1,Sheet4!$A$1:$M$1,0),0) -> 0 | ... Z152: =VLOOKUP($B152,Sheet4!$A$1:$M$4092,MATCH('MASTER DATA'!Z$1,Sheet4!$A$1:$M$1,0),0) -> 0
A153: 152 | B153: 32210292 | C153: OSHO COMPUTER ISOLI | D153: MS-CIT NCR-2017 | E153: Rural | F153: ISOLI | G153: Chikhali | H153: Buldhana | I153: Maharashtra | J153: AT POST ISOLIISOLI-444301 | K153: 9921265930 | L153: -9921265930 | M153: 32210292@mkcl.org | N153: Kumar Katare | O153: =VLOOKUP($B153,Sheet4!$A$1:$M$4092,MATCH('MASTER DATA'!O$1,Sheet4!$A$1:$M$1,0),0) -> 30 | P153: =VLOOKUP($B153,Sheet4!$A$1:$M$4092,MATCH('MASTER DATA'!P$1,Sheet4!$A$1:$M$1,0),0) -> 13 | Q153: =VLOOKUP($B153,Sheet4!$A$1:$M$4092,MATCH('MASTER DATA'!Q$1,Sheet4!$A$1:$M$1,0),0) -> 12 | R153: =VLOOKUP($B153,Sheet4!$A$1:$M$4092,MATCH('MASTER DATA'!R$1,Sheet4!$A$1:$M$1,0),0) -> 99 | S153: =VLOOKUP($B153,Sheet4!$A$1:$M$4092,MATCH('MASTER DATA'!S$1,Sheet4!$A$1:$M$1,0),0) -> 26 | T153: =VLOOKUP($B153,Sheet4!$A$1:$M$4092,MATCH('MASTER DATA'!T$1,Sheet4!$A$1:$M$1,0),0) -> 0 | U153: =VLOOKUP($B153,Sheet4!$A$1:$M$4092,MATCH('MASTER DATA'!U$1,Sheet4!$A$1:$M$1,0),0) -> 18 | V153: =VLOOKUP($B153,Sheet4!$A$1:$M$4092,MATCH('MASTER DATA'!V$1,Sheet4!$A$1:$M$1,0),0) -> 0 | ... Z153: =VLOOKUP($B153,Sheet4!$A$1:$M$4092,MATCH('MASTER DATA'!Z$1,Sheet4!$A$1:$M$1,0),0) -> 2
A154: 153 | B154: 32210308 | C154: SHRIPAD COMPUTER CENTER | D154: MS-CIT NCR-2019 | E154: Rural | F154: BULDANA | G154: Buldhana | H154: Buldhana | I154: Maharashtra | J154: AT POST DONGARKHANDALA TQ DIST BULDANABULDANA-443001 | K154: 9860012316 | L154: - | M154: 32210308@mkcl.org | N154: Kumar Katare | O154: =VLOOKUP($B154,Sheet4!$A$1:$M$4092,MATCH('MASTER DATA'!O$1,Sheet4!$A$1:$M$1,0),0) -> 0 | P154: =VLOOKUP($B154,Sheet4!$A$1:$M$4092,MATCH('MASTER DATA'!P$1,Sheet4!$A$1:$M$1,0),0) -> 0 | Q154: =VLOOKUP($B154,Sheet4!$A$1:$M$4092,MATCH('MASTER DATA'!Q$1,Sheet4!$A$1:$M$1,0),0) -> 0 | R154: =VLOOKUP($B154,Sheet4!$A$1:$M$4092,MATCH('MASTER DATA'!R$1,Sheet4!$A$1:$M$1,0),0) -> 37 | S154: =VLOOKUP($B154,Sheet4!$A$1:$M$4092,MATCH('MASTER DATA'!S$1,Sheet4!$A$1:$M$1,0),0) -> 0 | T154: =VLOOKUP($B154,Sheet4!$A$1:$M$4092,MATCH('MASTER DATA'!T$1,Sheet4!$A$1:$M$1,0),0) -> 11 | U154: =VLOOKUP($B154,Sheet4!$A$1:$M$4092,MATCH('MASTER DATA'!U$1,Sheet4!$A$1:$M$1,0),0) -> 0 | V154: =VLOOKUP($B154,Sheet4!$A$1:$M$4092,MATCH('MASTER DATA'!V$1,Sheet4!$A$1:$M$1,0),0) -> 31 | ... Z154: =VLOOKUP($B154,Sheet4!$A$1:$M$4092,MATCH('MASTER DATA'!Z$1,Sheet4!$A$1:$M$1,0),0) -> 12
A155: 154 | B155: 32210312 | C155: ICON COMPUTER | D155: MS-CIT NCR-2019 | E155: Rural | F155: Sutala Bk. | G155: Khamgaon | H155: Buldhana | I155: Maharashtra | J155: SHIVAJI NAGARSUTALA BK.-444312 | K155: 9890550058 | L155: - | M155: 32210312@mkcl.org | N155: Kumar Katare | O155: =VLOOKUP($B155,Sheet4!$A$1:$M$4092,MATCH('MASTER DATA'!O$1,Sheet4!$A$1:$M$1,0),0) -> 0 | P155: =VLOOKUP($B155,Sheet4!$A$1:$M$4092,MATCH('MASTER DATA'!P$1,Sheet4!$A$1:$M$1,0),0) -> 0 | Q155: =VLOOKUP($B155,Sheet4!$A$1:$M$4092,MATCH('MASTER DATA'!Q$1,Sheet4!$A$1:$M$1,0),0) -> 0 | R155: =VLOOKUP($B155,Sheet4!$A$1:$M$4092,MATCH('MASTER DATA'!R$1,Sheet4!$A$1:$M$1,0),0) -> 66 | S155: =VLOOKUP($B155,Sheet4!$A$1:$M$4092,MATCH('MASTER DATA'!S$1,Sheet4!$A$1:$M$1,0),0) -> 0 | T155: =VLOOKUP($B155,Sheet4!$A$1:$M$4092,MATCH('MASTER DATA'!T$1,Sheet4!$A$1:$M$1,0),0) -> 0 | U155: =VLOOKUP($B155,Sheet4!$A$1:$M$4092,MATCH('MASTER DATA'!U$1,Sheet4!$A$1:$M$1,0),0) -> 5 | V155: =VLOOKUP($B155,Sheet4!$A$1:$M$4092,MATCH('MASTER DATA'!V$1,Sheet4!$A$1:$M$1,0),0) -> 6 | ... Z155: =VLOOKUP($B155,Sheet4!$A$1:$M$4092,MATCH('MASTER DATA'!Z$1,Sheet4!$A$1:$M$1,0),0) -> 1
A156: 155 | B156: 34210002 | C156: Rainbow Computers | D156: MS-CIT Renewed | E156: Urban | F156: Warora | G156: Warora | H156: Chandrapur | I156: Maharashtra | J156: HANUMAN WARD, NEHARU SQUARE YATRA ROAD WARORAWARORA-442907 | K156: 9822706916 | L156: 07176-282325 | M156: 34210002@mkcl.org | N156: Kumar Katare | O156: =VLOOKUP($B156,Sheet4!$A$1:$M$4092,MATCH('MASTER DATA'!O$1,Sheet4!$A$1:$M$1,0),0) -> 79 | P156: =VLOOKUP($B156,Sheet4!$A$1:$M$4092,MATCH('MASTER DATA'!P$1,Sheet4!$A$1:$M$1,0),0) -> 100 | Q156: =VLOOKUP($B156,Sheet4!$A$1:$M$4092,MATCH('MASTER DATA'!Q$1,Sheet4!$A$1:$M$1,0),0) -> 13 | R156: =VLOOKUP($B156,Sheet4!$A$1:$M$4092,MATCH('MASTER DATA'!R$1,Sheet4!$A$1:$M$1,0),0) -> 515 | S156: =VLOOKUP($B156,Sheet4!$A$1:$M$4092,MATCH('MASTER DATA'!S$1,Sheet4!$A$1:$M$1,0),0) -> 94 | T156: =VLOOKUP($B156,Sheet4!$A$1:$M$4092,MATCH('MASTER DATA'!T$1,Sheet4!$A$1:$M$1,0),0) -> 9 | U156: =VLOOKUP($B156,Sheet4!$A$1:$M$4092,MATCH('MASTER DATA'!U$1,Sheet4!$A$1:$M$1,0),0) -> 133 | V156: =VLOOKUP($B156,Sheet4!$A$1:$M$4092,MATCH('MASTER DATA'!V$1,Sheet4!$A$1:$M$1,0),0) -> 46 | ... Z156: =VLOOKUP($B156,Sheet4!$A$1:$M$4092,MATCH('MASTER DATA'!Z$1,Sheet4!$A$1:$M$1,0),0) -> 48
A157: 156 | B157: 34210004 | C157: Kishor Computer Education | D157: MS-CIT Renewed | E157: Urban | F157: Bhadrawati | G157: Bhadrawati | H157: Chandrapur | I157: Maharashtra | J157: IN FRONT OF NAGAR PARISHAD, BAZAR WARD, MAIN ROAD, BHADRAWATI, TA. BHADRAWATI, DIST. CHANDRAPURBHADRAWATI-442902 | K157: 9822472807 | L157: 07175-265816 | M157: 34210004@mkcl.org | N157: Kumar Katare | O157: =VLOOKUP($B157,Sheet4!$A$1:$M$4092,MATCH('MASTER DATA'!O$1,Sheet4!$A$1:$M$1,0),0) -> 104 | P157: =VLOOKUP($B157,Sheet4!$A$1:$M$4092,MATCH('MASTER DATA'!P$1,Sheet4!$A$1:$M$1,0),0) -> 79 | Q157: =VLOOKUP($B157,Sheet4!$A$1:$M$4092,MATCH('MASTER DATA'!Q$1,Sheet4!$A$1:$M$1,0),0) -> 102 | R157: =VLOOKUP($B157,Sheet4!$A$1:$M$4092,MATCH('MASTER DATA'!R$1,Sheet4!$A$1:$M$1,0),0) -> 613 | S157: =VLOOKUP($B157,Sheet4!$A$1:$M$4092,MATCH('MASTER DATA'!S$1,Sheet4!$A$1:$M$1,0),0) -> 394 | T157: =VLOOKUP($B157,Sheet4!$A$1:$M$4092,MATCH('MASTER DATA'!T$1,Sheet4!$A$1:$M$1,0),0) -> 59 | U157: =VLOOKUP($B157,Sheet4!$A$1:$M$4092,MATCH('MASTER DATA'!U$1,Sheet4!$A$1:$M$1,0),0) -> 99 | V157: =VLOOKUP($B157,Sheet4!$A$1:$M$4092,MATCH('MASTER DATA'!V$1,Sheet4!$A$1:$M$1,0),0) -> 67 | ... Z157: =VLOOKUP($B157,Sheet4!$A$1:$M$4092,MATCH('MASTER DATA'!Z$1,Sheet4!$A$1:$M$1,0),0) -> 18
A158: 157 | B158: 34210015 | C158: Apex Computer | D158: MS-CIT Renewed | E158: Rural | F158: Gondpipari | G158: Gaudpimpri | H158: Chandrapur | I158: Maharashtra | J158: NEAR OLD BUS STAND,C/O ADKUJI CHINTAWAR GONDPIPARIGONDPIPARI-442702 | K158: 9423632918 | L158: 07171-220426 | M158: 34210015@mkcl.org | N158: Kumar Katare | O158: =VLOOKUP($B158,Sheet4!$A$1:$M$4092,MATCH('MASTER DATA'!O$1,Sheet4!$A$1:$M$1,0),0) -> 82 | P158: =VLOOKUP($B158,Sheet4!$A$1:$M$4092,MATCH('MASTER DATA'!P$1,Sheet4!$A$1:$M$1,0),0) -> 102 | Q158: =VLOOKUP($B158,Sheet4!$A$1:$M$4092,MATCH('MASTER DATA'!Q$1,Sheet4!$A$1:$M$1,0),0) -> 162 | R158: =VLOOKUP($B158,Sheet4!$A$1:$M$4092,MATCH('MASTER DATA'!R$1,Sheet4!$A$1:$M$1,0),0) -> 427 | S158: =VLOOKUP($B158,Sheet4!$A$1:$M$4092,MATCH('MASTER DATA'!S$1,Sheet4!$A$1:$M$1,0),0) -> 249 | T158: =VLOOKUP($B158,Sheet4!$A$1:$M$4092,MATCH('MASTER DATA'!T$1,Sheet4!$A$1:$M$1,0),0) -> 25 | U158: =VLOOKUP($B158,Sheet4!$A$1:$M$4092,MATCH('MASTER DATA'!U$1,Sheet4!$A$1:$M$1,0),0) -> 108 | V158: =VLOOKUP($B158,Sheet4!$A$1:$M$4092,MATCH('MASTER DATA'!V$1,Sheet4!$A$1:$M$1,0),0) -> 38 | ... Z158: =VLOOKUP($B158,Sheet4!$A$1:$M$4092,MATCH('MASTER DATA'!Z$1,Sheet4!$A$1:$M$1,0),0) -> 76
A159: 158 | B159: 34210127 | C159: SUCCESS COMPUTER 'S | D159: MS-CIT Renewed | E159: Urban | F159: SAOLI | G159: Savali | H159: Chandrapur | I159: Maharashtra | J159: C/O SHANKARRAO BALLAMWAR COMPLEX,BEHIND BUS STAND AT-POST-TAH-SAOLI,DIST-CHANDRAPURSAOLI-441225 | K159: 9764452577 | L159: 07174-274813 | M159: 34210127@mkcl.org | N159: Kumar Katare | O159: =VLOOKUP($B159,Sheet4!$A$1:$M$4092,MATCH('MASTER DATA'!O$1,Sheet4!$A$1:$M$1,0),0) -> 199 | P159: =VLOOKUP($B159,Sheet4!$A$1:$M$4092,MATCH('MASTER DATA'!P$1,Sheet4!$A$1:$M$1,0),0) -> 30 | Q159: =VLOOKUP($B159,Sheet4!$A$1:$M$4092,MATCH('MASTER DATA'!Q$1,Sheet4!$A$1:$M$1,0),0) -> 102 | R159: =VLOOKUP($B159,Sheet4!$A$1:$M$4092,MATCH('MASTER DATA'!R$1,Sheet4!$A$1:$M$1,0),0) -> 188 | S159: =VLOOKUP($B159,Sheet4!$A$1:$M$4092,MATCH('MASTER DATA'!S$1,Sheet4!$A$1:$M$1,0),0) -> 43 | T159: =VLOOKUP($B159,Sheet4!$A$1:$M$4092,MATCH('MASTER DATA'!T$1,Sheet4!$A$1:$M$1,0),0) -> 28 | U159: =VLOOKUP($B159,Sheet4!$A$1:$M$4092,MATCH('MASTER DATA'!U$1,Sheet4!$A$1:$M$1,0),0) -> 2 | V159: =VLOOKUP($B159,Sheet4!$A$1:$M$4092,MATCH('MASTER DATA'!V$1,Sheet4!$A$1:$M$1,0),0) -> 9 | ... Z159: =VLOOKUP($B159,Sheet4!$A$1:$M$4092,MATCH('MASTER DATA'!Z$1,Sheet4!$A$1:$M$1,0),0) -> 39
A160: 159 | B160: 34210132 | C160: GLOBALVISION COMPUTER INSTITUTE WARORA | D160: MS-CIT Renewed | E160: Urban | F160: WARORA | G160: Warora | H160: Chandrapur | I160: Maharashtra | J160: KAMGAR CHOWK,NEAR SHIKSHAK SAHAKARI BANK WARORA, NEAR SHIKSHAK SAHAKARI BANK, WARORA, WARORAWARORA-442907 | K160: 9822690712 | L160: 07176-284659 | M160: 34210132@mkcl.org | N160: Kumar Katare | O160: =VLOOKUP($B160,Sheet4!$A$1:$M$4092,MATCH('MASTER DATA'!O$1,Sheet4!$A$1:$M$1,0),0) -> 64 | P160: =VLOOKUP($B160,Sheet4!$A$1:$M$4092,MATCH('MASTER DATA'!P$1,Sheet4!$A$1:$M$1,0),0) -> 24 | Q160: =VLOOKUP($B160,Sheet4!$A$1:$M$4092,MATCH('MASTER DATA'!Q$1,Sheet4!$A$1:$M$1,0),0) -> 56 | R160: =VLOOKUP($B160,Sheet4!$A$1:$M$4092,MATCH('MASTER DATA'!R$1,Sheet4!$A$1:$M$1,0),0) -> 569 | S160: =VLOOKUP($B160,Sheet4!$A$1:$M$4092,MATCH('MASTER DATA'!S$1,Sheet4!$A$1:$M$1,0),0) -> 181 | T160: =VLOOKUP($B160,Sheet4!$A$1:$M$4092,MATCH('MASTER DATA'!T$1,Sheet4!$A$1:$M$1,0),0) -> 49 | U160: =VLOOKUP($B160,Sheet4!$A$1:$M$4092,MATCH('MASTER DATA'!U$1,Sheet4!$A$1:$M$1,0),0) -> 100 | V160: =VLOOKUP($B160,Sheet4!$A$1:$M$4092,MATCH('MASTER DATA'!V$1,Sheet4!$A$1:$M$1,0),0) -> 20 | ... Z160: =VLOOKUP($B160,Sheet4!$A$1:$M$4092,MATCH('MASTER DATA'!Z$1,Sheet4!$A$1:$M$1,0),0) -> 2
A161: 160 | B161: 34210055 | C161: Global Computer Education | D161: MS-CIT Renewed | E161: Urban | F161: Chandrapur | G161: Chandrapur | H161: Chandrapur | I161: Maharashtra | J161: C/O PRAMOD SAHARE, FIRST FLOOR, HOUSE NO 1275, POLE NO C/547, WAGHOBA CHOWK ROAD, TUKUMCHANDRAPUR-442401 | K161: 9422139774 | L161: 07172-274147 | M161: 34210055@mkcl.org | N161: Kumar Katare | O161: =VLOOKUP($B161,Sheet4!$A$1:$M$4092,MATCH('MASTER DATA'!O$1,Sheet4!$A$1:$M$1,0),0) -> 39 | P161: =VLOOKUP($B161,Sheet4!$A$1:$M$4092,MATCH('MASTER DATA'!P$1,Sheet4!$A$1:$M$1,0),0) -> 32 | Q161: =VLOOKUP($B161,Sheet4!$A$1:$M$4092,MATCH('MASTER DATA'!Q$1,Sheet4!$A$1:$M$1,0),0) -> 50 | R161: =VLOOKUP($B161,Sheet4!$A$1:$M$4092,MATCH('MASTER DATA'!R$1,Sheet4!$A$1:$M$1,0),0) -> 169 | S161: =VLOOKUP($B161,Sheet4!$A$1:$M$4092,MATCH('MASTER DATA'!S$1,Sheet4!$A$1:$M$1,0),0) -> 102 | T161: =VLOOKUP($B161,Sheet4!$A$1:$M$4092,MATCH('MASTER DATA'!T$1,Sheet4!$A$1:$M$1,0),0) -> 34 | U161: =VLOOKUP($B161,Sheet4!$A$1:$M$4092,MATCH('MASTER DATA'!U$1,Sheet4!$A$1:$M$1,0),0) -> 57 | V161: =VLOOKUP($B161,Sheet4!$A$1:$M$4092,MATCH('MASTER DATA'!V$1,Sheet4!$A$1:$M$1,0),0) -> 16 | ... Z161: =VLOOKUP($B161,Sheet4!$A$1:$M$4092,MATCH('MASTER DATA'!Z$1,Sheet4!$A$1:$M$1,0),0) -> 23
A162: 161 | B162: 34210010 | C162: Bytes Infosys Computers | D162: MS-CIT Renewed | E162: Urban | F162: Chandrapur | G162: Chandrapur | H162: Chandrapur | I162: Maharashtra | J162: ANURADHA NIWAS, NEAR JANTA COLLEGE, CHANDRAPURCHANDRAPUR-442401 | K162: 9822113937 | L162: 07172-270369 | M162: 34210010@mkcl.org | N162: Kumar Katare | O162: =VLOOKUP($B162,Sheet4!$A$1:$M$4092,MATCH('MASTER DATA'!O$1,Sheet4!$A$1:$M$1,0),0) -> 59 | P162: =VLOOKUP($B162,Sheet4!$A$1:$M$4092,MATCH('MASTER DATA'!P$1,Sheet4!$A$1:$M$1,0),0) -> 50 | Q162: =VLOOKUP($B162,Sheet4!$A$1:$M$4092,MATCH('MASTER DATA'!Q$1,Sheet4!$A$1:$M$1,0),0) -> 17 | R162: =VLOOKUP($B162,Sheet4!$A$1:$M$4092,MATCH('MASTER DATA'!R$1,Sheet4!$A$1:$M$1,0),0) -> 257 | S162: =VLOOKUP($B162,Sheet4!$A$1:$M$4092,MATCH('MASTER DATA'!S$1,Sheet4!$A$1:$M$1,0),0) -> 58 | T162: =VLOOKUP($B162,Sheet4!$A$1:$M$4092,MATCH('MASTER DATA'!T$1,Sheet4!$A$1:$M$1,0),0) -> 3 | U162: =VLOOKUP($B162,Sheet4!$A$1:$M$4092,MATCH('MASTER DATA'!U$1,Sheet4!$A$1:$M$1,0),0) -> 75 | V162: =VLOOKUP($B162,Sheet4!$A$1:$M$4092,MATCH('MASTER DATA'!V$1,Sheet4!$A$1:$M$1,0),0) -> 17 | ... Z162: =VLOOKUP($B162,Sheet4!$A$1:$M$4092,MATCH('MASTER DATA'!Z$1,Sheet4!$A$1:$M$1,0),0) -> 85
A163: 162 | B163: 34210007 | C163: Micro Computer Technology And Cyber Academy | D163: MS-CIT Renewed | E163: Urban | F163: Ballarpur | G163: Ballarpur | H163: Chandrapur | I163: Maharashtra | J163: KUREKAR HOUSE, RAJENDRA WARD, TEACHERS COLONY BALLARPURBALLARPUR-442701 | K163: 9890303045 | L163: 07172-241098 | M163: 34210007@mkcl.org | N163: Kumar Katare | O163: =VLOOKUP($B163,Sheet4!$A$1:$M$4092,MATCH('MASTER DATA'!O$1,Sheet4!$A$1:$M$1,0),0) -> 39 | P163: =VLOOKUP($B163,Sheet4!$A$1:$M$4092,MATCH('MASTER DATA'!P$1,Sheet4!$A$1:$M$1,0),0) -> 28 | Q163: =VLOOKUP($B163,Sheet4!$A$1:$M$4092,MATCH('MASTER DATA'!Q$1,Sheet4!$A$1:$M$1,0),0) -> 17 | R163: =VLOOKUP($B163,Sheet4!$A$1:$M$4092,MATCH('MASTER DATA'!R$1,Sheet4!$A$1:$M$1,0),0) -> 107 | S163: =VLOOKUP($B163,Sheet4!$A$1:$M$4092,MATCH('MASTER DATA'!S$1,Sheet4!$A$1:$M$1,0),0) -> 90 | T163: =VLOOKUP($B163,Sheet4!$A$1:$M$4092,MATCH('MASTER DATA'!T$1,Sheet4!$A$1:$M$1,0),0) -> 33 | U163: =VLOOKUP($B163,Sheet4!$A$1:$M$4092,MATCH('MASTER DATA'!U$1,Sheet4!$A$1:$M$1,0),0) -> 57 | V163: =VLOOKUP($B163,Sheet4!$A$1:$M$4092,MATCH('MASTER DATA'!V$1,Sheet4!$A$1:$M$1,0),0) -> 14 | ... Z163: =VLOOKUP($B163,Sheet4!$A$1:$M$4092,MATCH('MASTER DATA'!Z$1,Sheet4!$A$1:$M$1,0),0) -> 6
A164: 163 | B164: 34210006 | C164: Shree Sai Computers | D164: MS-CIT Renewed | E164: Urban | F164: Warora | G164: Warora | H164: Chandrapur | I164: Maharashtra | J164: NEAR BANK OF MAHARASHTRA, AMBEDKAR CHOWK, WARORAWARORA-442907 | K164: 9689885740 | L164: 07176-281201 | M164: 34210006@mkcl.org | N164: Kumar Katare | O164: =VLOOKUP($B164,Sheet4!$A$1:$M$4092,MATCH('MASTER DATA'!O$1,Sheet4!$A$1:$M$1,0),0) -> 142 | P164: =VLOOKUP($B164,Sheet4!$A$1:$M$4092,MATCH('MASTER DATA'!P$1,Sheet4!$A$1:$M$1,0),0) -> 50 | Q164: =VLOOKUP($B164,Sheet4!$A$1:$M$4092,MATCH('MASTER DATA'!Q$1,Sheet4!$A$1:$M$1,0),0) -> 224 | R164: =VLOOKUP($B164,Sheet4!$A$1:$M$4092,MATCH('MASTER DATA'!R$1,Sheet4!$A$1:$M$1,0),0) -> 736 | S164: =VLOOKUP($B164,Sheet4!$A$1:$M$4092,MATCH('MASTER DATA'!S$1,Sheet4!$A$1:$M$1,0),0) -> 142 | T164: =VLOOKUP($B164,Sheet4!$A$1:$M$4092,MATCH('MASTER DATA'!T$1,Sheet4!$A$1:$M$1,0),0) -> 48 | U164: =VLOOKUP($B164,Sheet4!$A$1:$M$4092,MATCH('MASTER DATA'!U$1,Sheet4!$A$1:$M$1,0),0) -> 143 | V164: =VLOOKUP($B164,Sheet4!$A$1:$M$4092,MATCH('MASTER DATA'!V$1,Sheet4!$A$1:$M$1,0),0) -> 61 | ... Z164: =VLOOKUP($B164,Sheet4!$A$1:$M$4092,MATCH('MASTER DATA'!Z$1,Sheet4!$A$1:$M$1,0),0) -> 43
A165: 164 | B165: 34210095 | C165: Phoenix Computer Education | D165: MS-CIT Renewed | E165: Urban | F165: Chimur | G165: Chimur | H165: Chandrapur | I165: Maharashtra | J165: NUTAN ADARSHA COLONY, NEAR BUS STAND, CHIMURCHIMUR-442903 | K165: 9890072255 | L165: 07170-266097 | M165: 34210095@mkcl.org | N165: Kumar Katare | O165: =VLOOKUP($B165,Sheet4!$A$1:$M$4092,MATCH('MASTER DATA'!O$1,Sheet4!$A$1:$M$1,0),0) -> 241 | P165: =VLOOKUP($B165,Sheet4!$A$1:$M$4092,MATCH('MASTER DATA'!P$1,Sheet4!$A$1:$M$1,0),0) -> 161 | Q165: =VLOOKUP($B165,Sheet4!$A$1:$M$4092,MATCH('MASTER DATA'!Q$1,Sheet4!$A$1:$M$1,0),0) -> 118 | R165: =VLOOKUP($B165,Sheet4!$A$1:$M$4092,MATCH('MASTER DATA'!R$1,Sheet4!$A$1:$M$1,0),0) -> 729 | S165: =VLOOKUP($B165,Sheet4!$A$1:$M$4092,MATCH('MASTER DATA'!S$1,Sheet4!$A$1:$M$1,0),0) -> 224 | T165: =VLOOKUP($B165,Sheet4!$A$1:$M$4092,MATCH('MASTER DATA'!T$1,Sheet4!$A$1:$M$1,0),0) -> 13 | U165: =VLOOKUP($B165,Sheet4!$A$1:$M$4092,MATCH('MASTER DATA'!U$1,Sheet4!$A$1:$M$1,0),0) -> 180 | V165: =VLOOKUP($B165,Sheet4!$A$1:$M$4092,MATCH('MASTER DATA'!V$1,Sheet4!$A$1:$M$1,0),0) -> 94 | ... Z165: =VLOOKUP($B165,Sheet4!$A$1:$M$4092,MATCH('MASTER DATA'!Z$1,Sheet4!$A$1:$M$1,0),0) -> 85
... A206: 205 | B206: 25210015 | C206: Institute Of Information Technology | D206: MS-CIT Renewed | E206: Urban | F206: Hingoli | G206: Hingoli | H206: Hingoli | I206: Maharashtra | J206: FIRST FLOOR,SONAR GALLI,SADAR BAZARHINGOLI-431513 | K206: 9423141617 | L206: 02456-222648 | M206: 25210015@mkcl.org | N206: Kumar Katare | O206: =VLOOKUP($B206,Sheet4!$A$1:$M$4092,MATCH('MASTER DATA'!O$1,Sheet4!$A$1:$M$1,0),0) -> 32 | P206: =VLOOKUP($B206,Sheet4!$A$1:$M$4092,MATCH('MASTER DATA'!P$1,Sheet4!$A$1:$M$1,0),0) -> 2 | Q206: =VLOOKUP($B206,Sheet4!$A$1:$M$4092,MATCH('MASTER DATA'!Q$1,Sheet4!$A$1:$M$1,0),0) -> 31 | R206: =VLOOKUP($B206,Sheet4!$A$1:$M$4092,MATCH('MASTER DATA'!R$1,Sheet4!$A$1:$M$1,0),0) -> 140 | S206: =VLOOKUP($B206,Sheet4!$A$1:$M$4092,MATCH('MASTER DATA'!S$1,Sheet4!$A$1:$M$1,0),0) -> 91 | T206: =VLOOKUP($B206,Sheet4!$A$1:$M$4092,MATCH('MASTER DATA'!T$1,Sheet4!$A$1:$M$1,0),0) -> 19 | U206: =VLOOKUP($B206,Sheet4!$A$1:$M$4092,MATCH('MASTER DATA'!U$1,Sheet4!$A$1:$M$1,0),0) -> 30 | V206: =VLOOKUP($B206,Sheet4!$A$1:$M$4092,MATCH('MASTER DATA'!V$1,Sheet4!$A$1:$M$1,0),0) -> 10 | ... Z206: =VLOOKUP($B206,Sheet4!$A$1:$M$4092,MATCH('MASTER DATA'!Z$1,Sheet4!$A$1:$M$1,0),0) -> 3
A207: 206 | B207: 25210110 | C207: BHAGYADAM COMPUTER CENTER | D207: MS-CIT NCR-2019 | E207: Urban | F207: Basmat | G207: Basamat | H207: Hingoli | I207: Maharashtra | J207: BANK COLONYBASMAT-431512 | K207: 9175900633 | L207: -917 | M207: 25210110@mkcl.org | N207: Kumar Katare | O207: =VLOOKUP($B207,Sheet4!$A$1:$M$4092,MATCH('MASTER DATA'!O$1,Sheet4!$A$1:$M$1,0),0) -> 0 | P207: =VLOOKUP($B207,Sheet4!$A$1:$M$4092,MATCH('MASTER DATA'!P$1,Sheet4!$A$1:$M$1,0),0) -> 41 | Q207: =VLOOKUP($B207,Sheet4!$A$1:$M$4092,MATCH('MASTER DATA'!Q$1,Sheet4!$A$1:$M$1,0),0) -> 0 | R207: =VLOOKUP($B207,Sheet4!$A$1:$M$4092,MATCH('MASTER DATA'!R$1,Sheet4!$A$1:$M$1,0),0) -> 63 | S207: =VLOOKUP($B207,Sheet4!$A$1:$M$4092,MATCH('MASTER DATA'!S$1,Sheet4!$A$1:$M$1,0),0) -> 0 | T207: =VLOOKUP($B207,Sheet4!$A$1:$M$4092,MATCH('MASTER DATA'!T$1,Sheet4!$A$1:$M$1,0),0) -> 0 | U207: =VLOOKUP($B207,Sheet4!$A$1:$M$4092,MATCH('MASTER DATA'!U$1,Sheet4!$A$1:$M$1,0),0) -> 13 | V207: =VLOOKUP($B207,Sheet4!$A$1:$M$4092,MATCH('MASTER DATA'!V$1,Sheet4!$A$1:$M$1,0),0) -> 12 | ... Z207: =VLOOKUP($B207,Sheet4!$A$1:$M$4092,MATCH('MASTER DATA'!Z$1,Sheet4!$A$1:$M$1,0),0) -> 0
A208: 207 | B208: 11210035 | C208: Tapasya Computers,Faizpur | D208: MS-CIT Renewed | E208: Rural | F208: Faizpur | G208: Yaval | H208: Jalgaon | I208: Maharashtra | J208: 1ST FLOOR,BAZAR SAMITI, YAWAL ROAD, FAIZPUR-425503 | K208: 9371166415 | L208: 02585-245015 | M208: 11210035@mkcl.org | N208: Kumar Katare | O208: =VLOOKUP($B208,Sheet4!$A$1:$M$4092,MATCH('MASTER DATA'!O$1,Sheet4!$A$1:$M$1,0),0) -> 30 | P208: =VLOOKUP($B208,Sheet4!$A$1:$M$4092,MATCH('MASTER DATA'!P$1,Sheet4!$A$1:$M$1,0),0) -> 3 | Q208: =VLOOKUP($B208,Sheet4!$A$1:$M$4092,MATCH('MASTER DATA'!Q$1,Sheet4!$A$1:$M$1,0),0) -> 30 | R208: =VLOOKUP($B208,Sheet4!$A$1:$M$4092,MATCH('MASTER DATA'!R$1,Sheet4!$A$1:$M$1,0),0) -> 245 | S208: =VLOOKUP($B208,Sheet4!$A$1:$M$4092,MATCH('MASTER DATA'!S$1,Sheet4!$A$1:$M$1,0),0) -> 387 | T208: =VLOOKUP($B208,Sheet4!$A$1:$M$4092,MATCH('MASTER DATA'!T$1,Sheet4!$A$1:$M$1,0),0) -> 21 | U208: =VLOOKUP($B208,Sheet4!$A$1:$M$4092,MATCH('MASTER DATA'!U$1,Sheet4!$A$1:$M$1,0),0) -> 38 | V208: =VLOOKUP($B208,Sheet4!$A$1:$M$4092,MATCH('MASTER DATA'!V$1,Sheet4!$A$1:$M$1,0),0) -> 18 | ... Z208: =VLOOKUP($B208,Sheet4!$A$1:$M$4092,MATCH('MASTER DATA'!Z$1,Sheet4!$A$1:$M$1,0),0) -> 15
A209: 208 | B209: 11210003 | C209: IGM Computer Education | D209: MS-CIT Renewed | E209: Urban | F209: Jalgaon | G209: Jalgaon | H209: Jalgaon | I209: Maharashtra | J209: BASEMENT LATHI PLAZA, OPP. SHAHU MAHARAJ COMPLEXJALGAON-425001 | K209: 9822464931 | L209: 0257-2241851 | M209: 11210003@mkcl.org | N209: Kumar Katare | O209: =VLOOKUP($B209,Sheet4!$A$1:$M$4092,MATCH('MASTER DATA'!O$1,Sheet4!$A$1:$M$1,0),0) -> 34 | P209: =VLOOKUP($B209,Sheet4!$A$1:$M$4092,MATCH('MASTER DATA'!P$1,Sheet4!$A$1:$M$1,0),0) -> 16 | Q209: =VLOOKUP($B209,Sheet4!$A$1:$M$4092,MATCH('MASTER DATA'!Q$1,Sheet4!$A$1:$M$1,0),0) -> 33 | R209: =VLOOKUP($B209,Sheet4!$A$1:$M$4092,MATCH('MASTER DATA'!R$1,Sheet4!$A$1:$M$1,0),0) -> 141 | S209: =VLOOKUP($B209,Sheet4!$A$1:$M$4092,MATCH('MASTER DATA'!S$1,Sheet4!$A$1:$M$1,0),0) -> 53 | T209: =VLOOKUP($B209,Sheet4!$A$1:$M$4092,MATCH('MASTER DATA'!T$1,Sheet4!$A$1:$M$1,0),0) -> 56 | U209: =VLOOKUP($B209,Sheet4!$A$1:$M$4092,MATCH('MASTER DATA'!U$1,Sheet4!$A$1:$M$1,0),0) -> 57 | V209: =VLOOKUP($B209,Sheet4!$A$1:$M$4092,MATCH('MASTER DATA'!V$1,Sheet4!$A$1:$M$1,0),0) -> 83 | ... Z209: =VLOOKUP($B209,Sheet4!$A$1:$M$4092,MATCH('MASTER DATA'!Z$1,Sheet4!$A$1:$M$1,0),0) -> 10
A210: 209 | B210: 26210002 | C210: Shri Samarth Computers | D210: MS-CIT Renewed | E210: Urban | F210: Bhokardhan | G210: Bhokardan | H210: Jalna | I210: Maharashtra | J210: FULE MARKET SILLOD ROAD, BHOKARDAN BHOKARDHAN-431114 | K210: 9421643882 | L210: 02485-244677 | M210: 26210002@mkcl.org | N210: Sambhaji Tagad | O210: =VLOOKUP($B210,Sheet4!$A$1:$M$4092,MATCH('MASTER DATA'!O$1,Sheet4!$A$1:$M$1,0),0) -> 207 | P210: =VLOOKUP($B210,Sheet4!$A$1:$M$4092,MATCH('MASTER DATA'!P$1,Sheet4!$A$1:$M$1,0),0) -> 67 | Q210: =VLOOKUP($B210,Sheet4!$A$1:$M$4092,MATCH('MASTER DATA'!Q$1,Sheet4!$A$1:$M$1,0),0) -> 136 | R210: =VLOOKUP($B210,Sheet4!$A$1:$M$4092,MATCH('MASTER DATA'!R$1,Sheet4!$A$1:$M$1,0),0) -> 717 | S210: =VLOOKUP($B210,Sheet4!$A$1:$M$4092,MATCH('MASTER DATA'!S$1,Sheet4!$A$1:$M$1,0),0) -> 175 | T210: =VLOOKUP($B210,Sheet4!$A$1:$M$4092,MATCH('MASTER DATA'!T$1,Sheet4!$A$1:$M$1,0),0) -> 35 | U210: =VLOOKUP($B210,Sheet4!$A$1:$M$4092,MATCH('MASTER DATA'!U$1,Sheet4!$A$1:$M$1,0),0) -> 214 | V210: =VLOOKUP($B210,Sheet4!$A$1:$M$4092,MATCH('MASTER DATA'!V$1,Sheet4!$A$1:$M$1,0),0) -> 76 | ... Z210: =VLOOKUP($B210,Sheet4!$A$1:$M$4092,MATCH('MASTER DATA'!Z$1,Sheet4!$A$1:$M$1,0),0) -> 43
A211: 210 | B211: 26210061 | C211: Shree Seva Computers | D211: MS-CIT Renewed | E211: Rural | F211: Jalna | G211: Jalna | H211: Jalna | I211: Maharashtra | J211: NEAR Z P HIGH SCHOOL, AT POST SEVLI, TQ DIST JALNA JALNA-431203 | K211: 9921096777 | L211: 02481-253677 | M211: 26210061@mkcl.org | N211: Sambhaji Tagad | O211: =VLOOKUP($B211,Sheet4!$A$1:$M$4092,MATCH('MASTER DATA'!O$1,Sheet4!$A$1:$M$1,0),0) -> 60 | P211: =VLOOKUP($B211,Sheet4!$A$1:$M$4092,MATCH('MASTER DATA'!P$1,Sheet4!$A$1:$M$1,0),0) -> 10 | Q211: =VLOOKUP($B211,Sheet4!$A$1:$M$4092,MATCH('MASTER DATA'!Q$1,Sheet4!$A$1:$M$1,0),0) -> 34 | R211: =VLOOKUP($B211,Sheet4!$A$1:$M$4092,MATCH('MASTER DATA'!R$1,Sheet4!$A$1:$M$1,0),0) -> 160 | S211: =VLOOKUP($B211,Sheet4!$A$1:$M$4092,MATCH('MASTER DATA'!S$1,Sheet4!$A$1:$M$1,0),0) -> 90 | T211: =VLOOKUP($B211,Sheet4!$A$1:$M$4092,MATCH('MASTER DATA'!T$1,Sheet4!$A$1:$M$1,0),0) -> 13 | U211: =VLOOKUP($B211,Sheet4!$A$1:$M$4092,MATCH('MASTER DATA'!U$1,Sheet4!$A$1:$M$1,0),0) -> 34 | V211: =VLOOKUP($B211,Sheet4!$A$1:$M$4092,MATCH('MASTER DATA'!V$1,Sheet4!$A$1:$M$1,0),0) -> 0 | ... Z211: =VLOOKUP($B211,Sheet4!$A$1:$M$4092,MATCH('MASTER DATA'!Z$1,Sheet4!$A$1:$M$1,0),0) -> 0
A212: 211 | B212: 26210068 | C212: Pragati Computers | D212: MS-CIT Renewed | E212: Rural | F212: Dhawada | G212: Bhokardan | H212: Jalna | I212: Maharashtra | J212: AT.POST. DHAWADADHAWADA-431132 | K212: 9975890033 | L212: 02485-243790 | M212: 26210068@mkcl.org | N212: Sambhaji Tagad | O212: =VLOOKUP($B212,Sheet4!$A$1:$M$4092,MATCH('MASTER DATA'!O$1,Sheet4!$A$1:$M$1,0),0) -> 24 | P212: =VLOOKUP($B212,Sheet4!$A$1:$M$4092,MATCH('MASTER DATA'!P$1,Sheet4!$A$1:$M$1,0),0) -> 20 | Q212: =VLOOKUP($B212,Sheet4!$A$1:$M$4092,MATCH('MASTER DATA'!Q$1,Sheet4!$A$1:$M$1,0),0) -> 19 | R212: =VLOOKUP($B212,Sheet4!$A$1:$M$4092,MATCH('MASTER DATA'!R$1,Sheet4!$A$1:$M$1,0),0) -> 185 | S212: =VLOOKUP($B212,Sheet4!$A$1:$M$4092,MATCH('MASTER DATA'!S$1,Sheet4!$A$1:$M$1,0),0) -> 158 | T212: =VLOOKUP($B212,Sheet4!$A$1:$M$4092,MATCH('MASTER DATA'!T$1,Sheet4!$A$1:$M$1,0),0) -> 10 | U212: =VLOOKUP($B212,Sheet4!$A$1:$M$4092,MATCH('MASTER DATA'!U$1,Sheet4!$A$1:$M$1,0),0) -> 40 | V212: =VLOOKUP($B212,Sheet4!$A$1:$M$4092,MATCH('MASTER DATA'!V$1,Sheet4!$A$1:$M$1,0),0) -> 12 | ... Z212: =VLOOKUP($B212,Sheet4!$A$1:$M$4092,MATCH('MASTER DATA'!Z$1,Sheet4!$A$1:$M$1,0),0) -> 38
A213: 212 | B213: 26210025 | C213: Pragati Computers | D213: MS-CIT Renewed | E213: Rural | F213: Walsavangi | G213: Bhokardan | H213: Jalna | I213: Maharashtra | J213: AT POST WALSAVANGIWALSAVANGI-431132 | K213: 9423460426 | L213: 02485-243060 | M213: 26210025@mkcl.org | N213: Sambhaji Tagad | O213: =VLOOKUP($B213,Sheet4!$A$1:$M$4092,MATCH('MASTER DATA'!O$1,Sheet4!$A$1:$M$1,0),0) -> 8 | P213: =VLOOKUP($B213,Sheet4!$A$1:$M$4092,MATCH('MASTER DATA'!P$1,Sheet4!$A$1:$M$1,0),0) -> 34 | Q213: =VLOOKUP($B213,Sheet4!$A$1:$M$4092,MATCH('MASTER DATA'!Q$1,Sheet4!$A$1:$M$1,0),0) -> 33 | R213: =VLOOKUP($B213,Sheet4!$A$1:$M$4092,MATCH('MASTER DATA'!R$1,Sheet4!$A$1:$M$1,0),0) -> 369 | S213: =VLOOKUP($B213,Sheet4!$A$1:$M$4092,MATCH('MASTER DATA'!S$1,Sheet4!$A$1:$M$1,0),0) -> 147 | T213: =VLOOKUP($B213,Sheet4!$A$1:$M$4092,MATCH('MASTER DATA'!T$1,Sheet4!$A$1:$M$1,0),0) -> 10 | U213: =VLOOKUP($B213,Sheet4!$A$1:$M$4092,MATCH('MASTER DATA'!U$1,Sheet4!$A$1:$M$1,0),0) -> 59 | V213: =VLOOKUP($B213,Sheet4!$A$1:$M$4092,MATCH('MASTER DATA'!V$1,Sheet4!$A$1:$M$1,0),0) -> 28 | ... Z213: =VLOOKUP($B213,Sheet4!$A$1:$M$4092,MATCH('MASTER DATA'!Z$1,Sheet4!$A$1:$M$1,0),0) -> 13
